Workbook

Sheet WD40_Summary
A1: WD40_Summary | B1: Original researched inputs | C1: Bear | D1: Base | E1: Bull
A2: DCF value / USD per share | B2: ='WD40_DCF_original'!B28+0 -> 88.150296 | C2: ='WD40_DCF_bear'!B28+0 -> 80.578186 | D2: ='WD40_DCF_base'!B28+0 -> 159.17021 | E2: ='WD40_DCF_bull'!B28+0 -> 258.66159
A3: Operating value / USD m | B3: ='WD40_DCF_original'!B26+0 -> 1230.6412 | C3: ='WD40_DCF_bear'!B26+0 -> 1127.4086 | D3: ='WD40_DCF_base'!B26+0 -> 2198.8743 | E3: ='WD40_DCF_bull'!B26+0 -> 3555.2665
A4: Equity value / USD m | B4: ='WD40_DCF_original'!B27+0 -> 1201.7762 | C4: ='WD40_DCF_bear'!B27+0 -> 1098.5436 | D4: ='WD40_DCF_base'!B27+0 -> 2170.0093 | E4: ='WD40_DCF_bull'!B27+0 -> 3526.4015
A5: PV terminal value / USD m | B5: ='WD40_DCF_original'!B22+0 -> 670.76664 | C5: ='WD40_DCF_bear'!B22+0 -> 584.91124 | D5: ='WD40_DCF_base'!B22+0 -> 1490.9939 | E5: ='WD40_DCF_bull'!B22+0 -> 2699.9776
A6: Terminal value share | B6: ='WD40_DCF_original'!B29+0 -> 0.54505461 | C6: ='WD40_DCF_bear'!B29+0 -> 0.51881035 | D6: ='WD40_DCF_base'!B29+0 -> 0.67807143 | E6: ='WD40_DCF_bull'!B29+0 -> 0.75943042
A7: Historical reference / USD per share | B7: 216.04 | C7: 216.04 | D7: 216.04 | E7: 216.04
A8: DCF / historical reference minus 1 | B8: =(B2/B7)-1 -> -0.59197234 | C8: =(C2/C7)-1 -> -0.62702191 | D8: =(D2/D7)-1 -> -0.26323732 | E8: =(E2/E7)-1 -> 0.19728566
A9: EVA minus DCF / USD m | B9: ='WD40_DCF_original'!B35+0 -> 2.2737368e-13 | C9: ='WD40_DCF_bear'!B35+0 -> 2.2737368e-13 | D9: ='WD40_DCF_base'!B35+0 -> 0 | E9: ='WD40_DCF_bull'!B35+0 -> -4.5474735e-13
A10: Scenario input hash | B10: e4c1895827e92d2759c61c3392fe8d9bafdd00069c33ad8ba99cb38a559f8cab | C10: 7c94e410363005ee306c3716110f2043a39411978dbc63b690807a6312846c44 | D10: a3708c72cdd6414155499a3919eb1f26547f3aea16a29781732f53e4221c6525 | E10: f23ba87d738fcf1f513ee37ad47bda6c395533da52e4d31c9cf7907fbb71b2fe
A11: Scenario classification | B11: original_snapshot | C11: analyst_assumption | D11: analyst_assumption | E11: analyst_assumption
A12: Financial basis | B12: FY2025 retrospective; later filings with historical price | C12: FY2025 retrospective; later filings with historical price | D12: FY2025 retrospective; later filings with historical price | E12: FY2025 retrospective; later filings with historical price
A13: Price date | B13: 2025-08-29 | C13: 2025-08-29 | D13: 2025-08-29 | E13: 2025-08-29
A14: Excel calculation status | B14: Python/browser verification; native Excel calculation pending | C14: Python/browser verification; native Excel calculation pending | D14: Python/browser verification; native Excel calculation pending | E14: Python/browser verification; native Excel calculation pending

Sheet WD40_Methods
A1: WD40_Methods | B1: Low / USD per share | C1: Central / USD per share | D1: High / USD per share | E1: Status | F1: Range interpretation | G1: Limitations
A2: Trading peers · EV/EBITDA | B2: Unavailable | C2: Unavailable | D2: Unavailable | E2: missing_data | F2: observed_multiple_percentiles | G2: At least three verified same-date observations are required. Percentiles are descriptive observations, not business scenarios. The WD-40 per-share denominator is a valuation dilution proxy.
A3: Trading peers · P/E | B3: Unavailable | C3: Unavailable | D3: Unavailable | E3: missing_data | F3: observed_multiple_percentiles | G3: At least three verified same-date observations are required. Percentiles are descriptive observations, not business scenarios. The WD-40 per-share denominator is a valuation dilution proxy.
A4: Trading peers · EV/sales | B4: Unavailable | C4: Unavailable | D4: Unavailable | E4: missing_data | F4: observed_multiple_percentiles | G4: At least three verified same-date observations are required. Percentiles are descriptive observations, not business scenarios. The WD-40 per-share denominator is a valuation dilution proxy.
A5: Acquisition context · consideration/EBITDA | B5: ='WD40_Precedents'!B6+0 -> 100.5581 | C5: ='WD40_Precedents'!C6+0 -> 112.87914 | D5: ='WD40_Precedents'!D6+0 -> 174.33224 | E5: indicative | F5: announced_consideration_context | G5: Announced acquisition consideration is not a verified net-debt-adjusted EV. Adjacent oral-care and personal-care brands differ from maintenance products. Periods, growth and deal tax structures differ; no tax shield is subtracted. This contextual range does not establish a WD-40 control valuation.
A6: LBO · sponsor ability to pay | B6: ='WD40_LBO'!B127+0 -> 89.370301 | C6: ='WD40_LBO'!C127+0 -> 100.33908 | D6: ='WD40_LBO'!D127+0 -> 106.93407 | E6: illustrative | F6: buyer_return_hurdles | G6: Leverage, debt pricing, fees and exit multiple are analyst assumptions. Forecast FCFF is a valuation proxy; no lender-approved financing is asserted. Forward reported EBITDA uses an explicit constant-margin R&D and D&A bridge. Entry EBITDA is operating EBIT plus cash-flow D&A, not the issuer adjusted EBITDA measure. No interim sponsor distributions or additional equity contributions are modeled. The per-share denominator is the case dilution proxy.
A7: DDM · assumed dividend policy | B7: ='WD40_DDM'!B72+0 -> 66.255859 | C7: ='WD40_DDM'!C72+0 -> 83.27561 | D7: ='WD40_DDM'!D72+0 -> 105.82183 | E7: illustrative | F7: analyst_dividend_scenarios | G7: Dividend growth and cost of equity are explicit analyst assumptions, not a CAPM estimate. The $3.76 dividend is an annualized quarterly run rate, not total shareholder distributions. Payout coverage uses a constant-debt FCFE proxy; buybacks are not separately valued. Terminal dividend growth uses the operating case terminal growth.
A8: Strategic buyer · incremental synergies | B8: ='WD40_Synergies'!B66+0 -> 192.31365 | C8: ='WD40_Synergies'!C66+0 -> 225.45708 | D8: ='WD40_Synergies'!D66+0 -> 258.60052 | E8: illustrative | F8: buyer_cost_savings_scenarios | G8: No identified buyer or verified synergy plan is asserted. Savings are incremental to standalone margins; no acquired growth is added. A one-year run-rate implementation cost is paid up front without an assumed tax shield. No acquisition premium allocation or negotiated seller share is assumed.

Sheet WD40_Regions_bear
A1: WD40_Regions_bear | B1: americas | C1: eimea | D1: asiaPacific | E1: Consolidated
A2: Reported FY2025 revenue / USD m | B2: 290.599 | C2: 236.434 | D2: 92.952 | E2: =SUM(B2:D2) -> 619.985
A3: Explicit divestment revenue removal / USD m | B3: 0 | C3: 0 | D3: 0 | E3: =SUM(B3:D3) -> 0
A4: Revenue after removal / USD m | B4: =B2-B3 -> 290.599 | C4: =C2-C3 -> 236.434 | D4: =D2-D3 -> 92.952 | E4: =SUM(B4:D4) -> 619.985
A5: Analyst regional growth years 1-5 | B5: 0.01 | C5: 0.04 | D5: 0.06
A6: Terminal growth | B6: ='WD40_Inputs_bear'!B22+0 -> 0.025 | C6: ='WD40_Inputs_bear'!B22+0 -> 0.025 | D6: ='WD40_Inputs_bear'!B22+0 -> 0.025
A7: Y1 revenue growth | B7: =B5+0 -> 0.01 | C7: =C5+0 -> 0.04 | D7: =D5+0 -> 0.06 | E7: =(E8/E2)-1 -> 0.028936942
A8: Y1 regional revenue / USD m | B8: =B4*(1+B7) -> 293.50499 | C8: =C4*(1+C7) -> 245.89136 | D8: =D4*(1+D7) -> 98.52912 | E8: =SUM(B8:D8) -> 637.92547
A9: Y1 compressed Ginzu revenue / USD m | E9: ='WD40_DCF_bear'!C4+0 -> 637.92547
A10: Y1 Ginzu minus regional revenue / USD m | E10: =E9-E8 -> 0
A11: Y2 revenue growth | B11: =B5+0 -> 0.01 | C11: =C5+0 -> 0.04 | D11: =D5+0 -> 0.06 | E11: =(E12/E8)-1 -> 0.029286261
A12: Y2 regional revenue / USD m | B12: =B8*(1+B11) -> 296.44004 | C12: =C8*(1+C11) -> 255.72701 | D12: =D8*(1+D11) -> 104.44087 | E12: =SUM(B12:D12) -> 656.60792
A13: Y2 compressed Ginzu revenue / USD m | E13: ='WD40_DCF_bear'!D4+0 -> 656.94437
A14: Y2 Ginzu minus regional revenue / USD m | E14: =E13-E12 -> 0.33644672
A15: Y3 revenue growth | B15: =B5+0 -> 0.01 | C15: =C5+0 -> 0.04 | D15: =D5+0 -> 0.06 | E15: =(E16/E12)-1 -> 0.029637067
A16: Y3 regional revenue / USD m | B16: =B12*(1+B15) -> 299.40444 | C16: =C12*(1+C15) -> 265.95609 | D16: =D12*(1+D15) -> 110.70732 | E16: =SUM(B16:D16) -> 676.06785
A17: Y3 compressed Ginzu revenue / USD m | E17: ='WD40_DCF_bear'!E4+0 -> 676.53029
A18: Y3 Ginzu minus regional revenue / USD m | E18: =E17-E16 -> 0.46243506
A19: Y4 revenue growth | B19: =B5+0 -> 0.01 | C19: =C5+0 -> 0.04 | D19: =D5+0 -> 0.06 | E19: =(E20/E16)-1 -> 0.02998919
A20: Y4 regional revenue / USD m | B20: =B16*(1+B19) -> 302.39848 | C20: =C16*(1+C19) -> 276.59434 | D20: =D16*(1+D19) -> 117.34976 | E20: =SUM(B20:D20) -> 696.34258
A21: Y4 compressed Ginzu revenue / USD m | E21: ='WD40_DCF_bear'!F4+0 -> 696.70014
A22: Y4 Ginzu minus regional revenue / USD m | E22: =E21-E20 -> 0.3575572
A23: Y5 revenue growth | B23: =B5+0 -> 0.01 | C23: =C5+0 -> 0.04 | D23: =D5+0 -> 0.06 | E23: =(E24/E20)-1 -> 0.030342456
A24: Y5 regional revenue / USD m | B24: =B20*(1+B23) -> 305.42247 | C24: =C20*(1+C23) -> 287.65811 | D24: =D20*(1+D23) -> 124.39074 | E24: =SUM(B24:D24) -> 717.47133
A25: Y5 compressed Ginzu revenue / USD m | E25: ='WD40_DCF_bear'!G4+0 -> 717.47133
A26: Y5 Ginzu minus regional revenue / USD m | E26: =E25-E24 -> -2.2737368e-13
A27: Y6 revenue growth | B27: =B5-(((B5-B6)/5)*1)+0 -> 0.013 | C27: =C5-(((C5-C6)/5)*1)+0 -> 0.037 | D27: =D5-(((D5-D6)/5)*1)+0 -> 0.053 | E27: =(E28/E24)-1 -> 0.029557351
A28: Y6 regional revenue / USD m | B28: =B24*(1+B27) -> 309.39296 | C28: =C24*(1+C27) -> 298.30146 | D28: =D24*(1+D27) -> 130.98345 | E28: =SUM(B28:D28) -> 738.67788
A29: Y6 compressed Ginzu revenue / USD m | E29: ='WD40_DCF_bear'!H4+0 -> 738.17104
A30: Y6 Ginzu minus regional revenue / USD m | E30: =E29-E28 -> -0.50683349
A31: Y7 revenue growth | B31: =B5-(((B5-B6)/5)*2)+0 -> 0.016 | C31: =C5-(((C5-C6)/5)*2)+0 -> 0.034 | D31: =D5-(((D5-D6)/5)*2)+0 -> 0.046 | E31: =(E32/E28)-1 -> 0.028588613
A32: Y7 regional revenue / USD m | B32: =B28*(1+B31) -> 314.34325 | C32: =C28*(1+C31) -> 308.44371 | D32: =D28*(1+D31) -> 137.00869 | E32: =SUM(B32:D32) -> 759.79565
A33: Y7 compressed Ginzu revenue / USD m | E33: ='WD40_DCF_bear'!I4+0 -> 758.75731
A34: Y7 Ginzu minus regional revenue / USD m | E34: =E33-E32 -> -1.0383471
A35: Y8 revenue growth | B35: =B5-(((B5-B6)/5)*3)+0 -> 0.019 | C35: =C5-(((C5-C6)/5)*3)+0 -> 0.031 | D35: =D5-(((D5-D6)/5)*3)+0 -> 0.039 | E35: =(E36/E32)-1 -> 0.027477935
A36: Y8 regional revenue / USD m | B36: =B32*(1+B35) -> 320.31577 | C36: =C32*(1+C35) -> 318.00547 | D36: =D32*(1+D35) -> 142.35203 | E36: =SUM(B36:D36) -> 780.67327
A37: Y8 compressed Ginzu revenue / USD m | E37: ='WD40_DCF_bear'!J4+0 -> 779.1872
A38: Y8 Ginzu minus regional revenue / USD m | E38: =E37-E36 -> -1.4860679
A39: Y9 revenue growth | B39: =B5-(((B5-B6)/5)*4)+0 -> 0.022 | C39: =C5-(((C5-C6)/5)*4)+0 -> 0.028 | D39: =D5-(((D5-D6)/5)*4)+0 -> 0.032 | E39: =(E40/E36)-1 -> 0.026267538
A40: Y9 regional revenue / USD m | B40: =B36*(1+B39) -> 327.36272 | C40: =C36*(1+C39) -> 326.90962 | D40: =D36*(1+D39) -> 146.9073 | E40: =SUM(B40:D40) -> 801.17963
...

Sheet WD40_Regions_base
A1: WD40_Regions_base | B1: americas | C1: eimea | D1: asiaPacific | E1: Consolidated
A2: Reported FY2025 revenue / USD m | B2: 290.599 | C2: 236.434 | D2: 92.952 | E2: =SUM(B2:D2) -> 619.985
A3: Explicit divestment revenue removal / USD m | B3: 0 | C3: 0 | D3: 0 | E3: =SUM(B3:D3) -> 0
A4: Revenue after removal / USD m | B4: =B2-B3 -> 290.599 | C4: =C2-C3 -> 236.434 | D4: =D2-D3 -> 92.952 | E4: =SUM(B4:D4) -> 619.985
A5: Analyst regional growth years 1-5 | B5: 0.04 | C5: 0.07 | D5: 0.1
A6: Terminal growth | B6: ='WD40_Inputs_base'!B22+0 -> 0.025 | C6: ='WD40_Inputs_base'!B22+0 -> 0.025 | D6: ='WD40_Inputs_base'!B22+0 -> 0.025
A7: Y1 revenue growth | B7: =B5+0 -> 0.04 | C7: =C5+0 -> 0.07 | D7: =D5+0 -> 0.1 | E7: =(E8/E2)-1 -> 0.060436204
A8: Y1 regional revenue / USD m | B8: =B4*(1+B7) -> 302.22296 | C8: =C4*(1+C7) -> 252.98438 | D8: =D4*(1+D7) -> 102.2472 | E8: =SUM(B8:D8) -> 657.45454
A9: Y1 compressed Ginzu revenue / USD m | E9: ='WD40_DCF_base'!C4+0 -> 657.45454
A10: Y1 Ginzu minus regional revenue / USD m | E10: =E9-E8 -> 0
A11: Y2 revenue growth | B11: =B5+0 -> 0.04 | C11: =C5+0 -> 0.07 | D11: =D5+0 -> 0.1 | E11: =(E12/E8)-1 -> 0.060875
A12: Y2 regional revenue / USD m | B12: =B8*(1+B11) -> 314.31188 | C12: =C8*(1+C11) -> 270.69329 | D12: =D8*(1+D11) -> 112.47192 | E12: =SUM(B12:D12) -> 697.47708
A13: Y2 compressed Ginzu revenue / USD m | E13: ='WD40_DCF_base'!D4+0 -> 697.9172
A14: Y2 Ginzu minus regional revenue / USD m | E14: =E13-E12 -> 0.44011402
A15: Y3 revenue growth | B15: =B5+0 -> 0.04 | C15: =C5+0 -> 0.07 | D15: =D5+0 -> 0.1 | E15: =(E16/E12)-1 -> 0.061318426
A16: Y3 regional revenue / USD m | B16: =B12*(1+B15) -> 326.88435 | C16: =C12*(1+C15) -> 289.64182 | D16: =D12*(1+D15) -> 123.71911 | E16: =SUM(B16:D16) -> 740.24528
A17: Y3 compressed Ginzu revenue / USD m | E17: ='WD40_DCF_base'!E4+0 -> 740.87011
A18: Y3 Ginzu minus regional revenue / USD m | E18: =E17-E16 -> 0.62482677
A19: Y4 revenue growth | B19: =B5+0 -> 0.04 | C19: =C5+0 -> 0.07 | D19: =D5+0 -> 0.1 | E19: =(E20/E16)-1 -> 0.0617663
A20: Y4 regional revenue / USD m | B20: =B16*(1+B19) -> 339.95973 | C20: =C16*(1+C19) -> 309.91674 | D20: =D16*(1+D19) -> 136.09102 | E20: =SUM(B20:D20) -> 785.96749
A21: Y4 compressed Ginzu revenue / USD m | E21: ='WD40_DCF_base'!F4+0 -> 786.46653
A22: Y4 Ginzu minus regional revenue / USD m | E22: =E21-E20 -> 0.49903619
A23: Y5 revenue growth | B23: =B5+0 -> 0.04 | C23: =C5+0 -> 0.07 | D23: =D5+0 -> 0.1 | E23: =(E24/E20)-1 -> 0.06221843
A24: Y5 regional revenue / USD m | B24: =B20*(1+B23) -> 353.55812 | C24: =C20*(1+C23) -> 331.61092 | D24: =D20*(1+D23) -> 149.70013 | E24: =SUM(B24:D24) -> 834.86916
A25: Y5 compressed Ginzu revenue / USD m | E25: ='WD40_DCF_base'!G4+0 -> 834.86916
A26: Y5 Ginzu minus regional revenue / USD m | E26: =E25-E24 -> 0
A27: Y6 revenue growth | B27: =B5-(((B5-B6)/5)*1)+0 -> 0.037 | C27: =C5-(((C5-C6)/5)*1)+0 -> 0.061 | D27: =D5-(((D5-D6)/5)*1)+0 -> 0.085 | E27: =(E28/E24)-1 -> 0.05513969
A28: Y6 regional revenue / USD m | B28: =B24*(1+B27) -> 366.63977 | C28: =C24*(1+C27) -> 351.83918 | D28: =D24*(1+D27) -> 162.42464 | E28: =SUM(B28:D28) -> 880.90359
A29: Y6 compressed Ginzu revenue / USD m | E29: ='WD40_DCF_base'!H4+0 -> 880.14874
A30: Y6 Ginzu minus regional revenue / USD m | E30: =E29-E28 -> -0.75484988
A31: Y7 revenue growth | B31: =B5-(((B5-B6)/5)*2)+0 -> 0.034 | C31: =C5-(((C5-C6)/5)*2)+0 -> 0.052 | D31: =D5-(((D5-D6)/5)*2)+0 -> 0.07 | E31: =(E32/E28)-1 -> 0.047827157
A32: Y7 regional revenue / USD m | B32: =B28*(1+B31) -> 379.10552 | C32: =C28*(1+C31) -> 370.13482 | D32: =D28*(1+D31) -> 173.79436 | E32: =SUM(B32:D32) -> 923.0347
A33: Y7 compressed Ginzu revenue / USD m | E33: ='WD40_DCF_base'!I4+0 -> 921.45117
A34: Y7 Ginzu minus regional revenue / USD m | E34: =E33-E32 -> -1.58353
A35: Y8 revenue growth | B35: =B5-(((B5-B6)/5)*3)+0 -> 0.031 | C35: =C5-(((C5-C6)/5)*3)+0 -> 0.043 | D35: =D5-(((D5-D6)/5)*3)+0 -> 0.055 | E35: =(E36/E32)-1 -> 0.040330833
A36: Y8 regional revenue / USD m | B36: =B32*(1+B35) -> 390.85779 | C36: =C32*(1+C35) -> 386.05062 | D36: =D32*(1+D35) -> 183.35305 | E36: =SUM(B36:D36) -> 960.26146
A37: Y8 compressed Ginzu revenue / USD m | E37: ='WD40_DCF_base'!J4+0 -> 957.95701
A38: Y8 Ginzu minus regional revenue / USD m | E38: =E37-E36 -> -2.3044491
A39: Y9 revenue growth | B39: =B5-(((B5-B6)/5)*4)+0 -> 0.028 | C39: =C5-(((C5-C6)/5)*4)+0 -> 0.034 | D39: =D5-(((D5-D6)/5)*4)+0 -> 0.04 | E39: =(E40/E36)-1 -> 0.032703448
A40: Y9 regional revenue / USD m | B40: =B36*(1+B39) -> 401.80181 | C40: =C36*(1+C39) -> 399.17634 | D40: =D36*(1+D39) -> 190.68717 | E40: =SUM(B40:D40) -> 991.66532
...

Sheet WD40_Regions_bull
A1: WD40_Regions_bull | B1: americas | C1: eimea | D1: asiaPacific | E1: Consolidated
A2: Reported FY2025 revenue / USD m | B2: 290.599 | C2: 236.434 | D2: 92.952 | E2: =SUM(B2:D2) -> 619.985
A3: Explicit divestment revenue removal / USD m | B3: 0 | C3: 0 | D3: 0 | E3: =SUM(B3:D3) -> 0
A4: Revenue after removal / USD m | B4: =B2-B3 -> 290.599 | C4: =C2-C3 -> 236.434 | D4: =D2-D3 -> 92.952 | E4: =SUM(B4:D4) -> 619.985
A5: Analyst regional growth years 1-5 | B5: 0.06 | C5: 0.09 | D5: 0.13
A6: Terminal growth | B6: ='WD40_Inputs_bull'!B22+0 -> 0.03 | C6: ='WD40_Inputs_bull'!B22+0 -> 0.03 | D6: ='WD40_Inputs_bull'!B22+0 -> 0.03
A7: Y1 revenue growth | B7: =B5+0 -> 0.06 | C7: =C5+0 -> 0.09 | D7: =D5+0 -> 0.13 | E7: =(E8/E2)-1 -> 0.081935466
A8: Y1 regional revenue / USD m | B8: =B4*(1+B7) -> 308.03494 | C8: =C4*(1+C7) -> 257.71306 | D8: =D4*(1+D7) -> 105.03576 | E8: =SUM(B8:D8) -> 670.78376
A9: Y1 compressed Ginzu revenue / USD m | E9: ='WD40_DCF_bull'!C4+0 -> 670.78376
A10: Y1 Ginzu minus regional revenue / USD m | E10: =E9-E8 -> 1.1368684e-13
A11: Y2 revenue growth | B11: =B5+0 -> 0.06 | C11: =C5+0 -> 0.09 | D11: =D5+0 -> 0.13 | E11: =(E12/E8)-1 -> 0.082486971
A12: Y2 regional revenue / USD m | B12: =B8*(1+B11) -> 326.51704 | C12: =C8*(1+C11) -> 280.90724 | D12: =D8*(1+D11) -> 118.69041 | E12: =SUM(B12:D12) -> 726.11468
A13: Y2 compressed Ginzu revenue / USD m | E13: ='WD40_DCF_bull'!D4+0 -> 726.68542
A14: Y2 Ginzu minus regional revenue / USD m | E14: =E13-E12 -> 0.57073582
A15: Y3 revenue growth | B15: =B5+0 -> 0.06 | C15: =C5+0 -> 0.09 | D15: =D5+0 -> 0.13 | E15: =(E16/E12)-1 -> 0.083048075
A16: Y3 regional revenue / USD m | B16: =B12*(1+B15) -> 346.10806 | C16: =C12*(1+C15) -> 306.18889 | D16: =D12*(1+D15) -> 134.12016 | E16: =SUM(B16:D16) -> 786.41711
A17: Y3 compressed Ginzu revenue / USD m | E17: ='WD40_DCF_bull'!E4+0 -> 787.2458
A18: Y3 Ginzu minus regional revenue / USD m | E18: =E17-E16 -> 0.82868791
A19: Y4 revenue growth | B19: =B5+0 -> 0.06 | C19: =C5+0 -> 0.09 | D19: =D5+0 -> 0.13 | E19: =(E20/E16)-1 -> 0.083618609
A20: Y4 regional revenue / USD m | B20: =B16*(1+B19) -> 366.87454 | C20: =C16*(1+C19) -> 333.74589 | D20: =D16*(1+D19) -> 151.55578 | E20: =SUM(B20:D20) -> 852.17621
A21: Y4 compressed Ginzu revenue / USD m | E21: ='WD40_DCF_bull'!F4+0 -> 852.85314
A22: Y4 Ginzu minus regional revenue / USD m | E22: =E21-E20 -> 0.67693211
A23: Y5 revenue growth | B23: =B5+0 -> 0.06 | C23: =C5+0 -> 0.09 | D23: =D5+0 -> 0.13 | E23: =(E24/E20)-1 -> 0.084198377
A24: Y5 regional revenue / USD m | B24: =B20*(1+B23) -> 388.88701 | C24: =C20*(1+C23) -> 363.78302 | D24: =D20*(1+D23) -> 171.25803 | E24: =SUM(B24:D24) -> 923.92807
A25: Y5 compressed Ginzu revenue / USD m | E25: ='WD40_DCF_bull'!G4+0 -> 923.92807
A26: Y5 Ginzu minus regional revenue / USD m | E26: =E25-E24 -> 3.4106051e-13
A27: Y6 revenue growth | B27: =B5-(((B5-B6)/5)*1)+0 -> 0.054 | C27: =C5-(((C5-C6)/5)*1)+0 -> 0.078 | D27: =D5-(((D5-D6)/5)*1)+0 -> 0.11 | E27: =(E28/E24)-1 -> 0.073829728
A28: Y6 regional revenue / USD m | B28: =B24*(1+B27) -> 409.88691 | C28: =C24*(1+C27) -> 392.15809 | D28: =D24*(1+D27) -> 190.09642 | E28: =SUM(B28:D28) -> 992.14142
A29: Y6 compressed Ginzu revenue / USD m | E29: ='WD40_DCF_bull'!H4+0 -> 991.07015
A30: Y6 Ginzu minus regional revenue / USD m | E30: =E29-E28 -> -1.0712686
A31: Y7 revenue growth | B31: =B5-(((B5-B6)/5)*2)+0 -> 0.048 | C31: =C5-(((C5-C6)/5)*2)+0 -> 0.066 | D31: =D5-(((D5-D6)/5)*2)+0 -> 0.09 | E31: =(E32/E28)-1 -> 0.063162047
A32: Y7 regional revenue / USD m | B32: =B28*(1+B31) -> 429.56149 | C32: =C28*(1+C31) -> 418.04053 | D32: =D28*(1+D31) -> 207.2051 | E32: =SUM(B32:D32) -> 1054.8071
A33: Y7 compressed Ginzu revenue / USD m | E33: ='WD40_DCF_bull'!I4+0 -> 1052.5192
A34: Y7 Ginzu minus regional revenue / USD m | E34: =E33-E32 -> -2.2879345
A35: Y8 revenue growth | B35: =B5-(((B5-B6)/5)*3)+0 -> 0.042 | C35: =C5-(((C5-C6)/5)*3)+0 -> 0.054 | D35: =D5-(((D5-D6)/5)*3)+0 -> 0.07 | E35: =(E36/E32)-1 -> 0.052256121
A36: Y8 regional revenue / USD m | B36: =B32*(1+B35) -> 447.60307 | C36: =C32*(1+C35) -> 440.61471 | D36: =D32*(1+D35) -> 221.70945 | E36: =SUM(B36:D36) -> 1109.9272
A37: Y8 compressed Ginzu revenue / USD m | E37: ='WD40_DCF_bull'!J4+0 -> 1106.5504
A38: Y8 Ginzu minus regional revenue / USD m | E38: =E37-E36 -> -3.3768554
A39: Y9 revenue growth | B39: =B5-(((B5-B6)/5)*4)+0 -> 0.036 | C39: =C5-(((C5-C6)/5)*4)+0 -> 0.042 | D39: =D5-(((D5-D6)/5)*4)+0 -> 0.05 | E39: =(E40/E36)-1 -> 0.041178376
A40: Y9 regional revenue / USD m | B40: =B36*(1+B39) -> 463.71678 | C40: =C36*(1+C39) -> 459.12053 | D40: =D36*(1+D39) -> 232.79493 | E40: =SUM(B40:D40) -> 1155.6322
...

Sheet WD40_Inputs_original
A1: WD40_Inputs_original | B1: Value
A2: Revenue FY2025 / USD m | B2: 619.985
A3: Reported EBIT FY2025 / USD m | B3: 103.793
A4: Adjusted book equity / USD m | B4: 268.472
A5: Interest-bearing debt / USD m | B5: 86.995
A6: Cash / USD m | B6: 58.13
A7: Nonoperating assets / USD m | B7: 0
A8: Minority interests / USD m | B8: 0
A9: Valuation dilution proxy / million shares | B9: 13.633263
A10: Historical reference price / USD per share | B10: 216.04
A11: Normalized starting tax rate | B11: 0.22200028
A12: Terminal tax rate | B12: 0.25
A13: Revenue growth year 1 | B13: 0.05
A14: Revenue growth years 2-5 | B14: =B13+0 -> 0.05
A15: Adjusted EBIT margin year 1 | B15: =B44/B2 -> 0.17106812
A16: Target adjusted EBIT margin | B16: =B15+0 -> 0.17106812
A17: Margin convergence year | B17: 5
A18: Sales to capital years 1-5 | B18: 2
A19: Sales to capital years 6-10 | B19: =B18+0 -> 2
A20: WACC years 1-5 | B20: 0.09
A21: Terminal WACC | B21: 0.08
A22: Terminal growth | B22: 0.025
A23: Use explicit terminal ROIC / 1=yes | B23: 0
A24: Explicit terminal ROIC | B24: 0.15
A25: Current R&D / USD m | B25: 8.7
A26: R&D amortization life / years | B26: 3
A27: Capitalize R&D / 1=yes | B27: 1
A28: Starting NOL / USD m | B28: 0
A29: Hold starting tax rate / 1=yes | B29: 0
A30: Override reinvestment timing / 1=yes | B30: 0
A31: Reinvestment growth lead / years | B31: 1
... A41: R&D 4 years prior / USD m | B41: 5.6
A42: R&D amortization / USD m | B42: =0+IF(1<=B26,(B38/B26),0)+IF(2<=B26,(B39/B26),0)+IF(3<=B26,(B40/B26),0)+IF(4<=B26,(B41/B26),0) -> 6.4333333
A43: Unamortized R&D asset / USD m | B43: =B25+IF(1<B26,(B38*((B26-1)/B26)),0)+IF(2<B26,(B39*((B26-2)/B26)),0)+IF(3<B26,(B40*((B26-3)/B26)),0)+IF(4<B26,(B41*((B26-4)/B26)),0) -> 16.1
A44: R&D-adjusted base EBIT / USD m | B44: =B3+IF(B27=1,(B25-B42),0) -> 106.05967
A45: Base invested capital / USD m | B45: =B4+B5-B6+IF(B27=1,B43,0) -> 313.437
A46: Effective terminal tax rate | B46: =IF(B29=1,B11,B12) -> 0.25
A47: Effective terminal ROIC | B47: =IF(B23=1,B24,B21) -> 0.08
A48: Cash after explicit haircut / USD m | B48: =B6-IF(B37=1,(B35*(B12-B36)),0) -> 58.13

Sheet WD40_DCF_original
A1: WD40_DCF_original | B1: Base | C1: Y1 | D1: Y2 | E1: Y3 | F1: Y4 | G1: Y5 | H1: Y6 | I1: Y7 | J1: Y8 | K1: Y9 | L1: Y10 | M1: Terminal
A2: Year | B2: 0 | C2: 1 | D2: 2 | E2: 3 | F2: 4 | G2: 5 | H2: 6 | I2: 7 | J2: 8 | K2: 9 | L2: 10 | M2: 11
A3: Revenue growth | C3: ='WD40_Inputs_original'!B13+0 -> 0.05 | D3: ='WD40_Inputs_original'!B14+0 -> 0.05 | E3: ='WD40_Inputs_original'!B14+0 -> 0.05 | F3: ='WD40_Inputs_original'!B14+0 -> 0.05 | G3: ='WD40_Inputs_original'!B14+0 -> 0.05 | H3: ='WD40_Inputs_original'!B14+0-((('WD40_Inputs_original'!B14+0-'WD40_Inputs_original'!B22+0)/5)*1) -> 0.045 | I3: ='WD40_Inputs_original'!B14+0-((('WD40_Inputs_original'!B14+0-'WD40_Inputs_original'!B22+0)/5)*2) -> 0.04 | J3: ='WD40_Inputs_original'!B14+0-((('WD40_Inputs_original'!B14+0-'WD40_Inputs_original'!B22+0)/5)*3) -> 0.035 | K3: ='WD40_Inputs_original'!B14+0-((('WD40_Inputs_original'!B14+0-'WD40_Inputs_original'!B22+0)/5)*4) -> 0.03 | L3: ='WD40_Inputs_original'!B14+0-((('WD40_Inputs_original'!B14+0-'WD40_Inputs_original'!B22+0)/5)*5) -> 0.025 | M3: ='WD40_Inputs_original'!B22+0 -> 0.025
A4: Revenue / USD m | B4: ='WD40_Inputs_original'!B2+0 -> 619.985 | C4: =B4*(1+C3) -> 650.98425 | D4: =C4*(1+D3) -> 683.53346 | E4: =D4*(1+E3) -> 717.71014 | F4: =E4*(1+F3) -> 753.59564 | G4: =F4*(1+G3) -> 791.27542 | H4: =G4*(1+H3) -> 826.88282 | I4: =H4*(1+I3) -> 859.95813 | J4: =I4*(1+J3) -> 890.05667 | ... M4: =L4*(1+M3) -> 963.16926
A5: Adjusted EBIT margin | B5: =B6/B4 -> 0.17106812 | C5: ='WD40_Inputs_original'!B15+0 -> 0.17106812 | D5: =IF(2>'WD40_Inputs_original'!B17+0,'WD40_Inputs_original'!B16+0,'WD40_Inputs_original'!B16+0-((('WD40_Inputs_original'!B16+0-'WD40_Inputs_original'!B15+0)/'WD40_Inputs_original'!B17+0)*('WD40_Inputs_original'!B17+0-2))) -> 0.17106812 | E5: =IF(3>'WD40_Inputs_original'!B17+0,'WD40_Inputs_original'!B16+0,'WD40_Inputs_original'!B16+0-((('WD40_Inputs_original'!B16+0-'WD40_Inputs_original'!B15+0)/'WD40_Inputs_original'!B17+0)*('WD40_Inputs_original'!B17+0-3))) -> 0.17106812 | F5: =IF(4>'WD40_Inputs_original'!B17+0,'WD40_Inputs_original'!B16+0,'WD40_Inputs_original'!B16+0-((('WD40_Inputs_original'!B16+0-'WD40_Inputs_original'!B15+0)/'WD40_Inputs_original'!B17+0)*('WD40_Inputs_original'!B17+0-4))) -> 0.17106812 | G5: =IF(5>'WD40_Inputs_original'!B17+0,'WD40_Inputs_original'!B16+0,'WD40_Inputs_original'!B16+0-((('WD40_Inputs_original'!B16+0-'WD40_Inputs_original'!B15+0)/'WD40_Inputs_original'!B17+0)*('WD40_Inputs_original'!B17+0-5))) -> 0.17106812 | H5: =IF(6>'WD40_Inputs_original'!B17+0,'WD40_Inputs_original'!B16+0,'WD40_Inputs_original'!B16+0-((('WD40_Inputs_original'!B16+0-'WD40_Inputs_original'!B15+0)/'WD40_Inputs_original'!B17+0)*('WD40_Inputs_original'!B17+0-6))) -> 0.17106812 | I5: =IF(7>'WD40_Inputs_original'!B17+0,'WD40_Inputs_original'!B16+0,'WD40_Inputs_original'!B16+0-((('WD40_Inputs_original'!B16+0-'WD40_Inputs_original'!B15+0)/'WD40_Inputs_original'!B17+0)*('WD40_Inputs_original'!B17+0-7))) -> 0.17106812 | J5: =IF(8>'WD40_Inputs_original'!B17+0,'WD40_Inputs_original'!B16+0,'WD40_Inputs_original'!B16+0-((('WD40_Inputs_original'!B16+0-'WD40_Inputs_original'!B15+0)/'WD40_Inputs_original'!B17+0)*('WD40_Inputs_original'!B17+0-8))) -> 0.17106812 | K5: =IF(9>'WD40_Inputs_original'!B17+0,'WD40_Inputs_original'!B16+0,'WD40_Inputs_original'!B16+0-((('WD40_Inputs_original'!B16+0-'WD40_Inputs_original'!B15+0)/'WD40_Inputs_original'!B17+0)*('WD40_Inputs_original'!B17+0-9))) -> 0.17106812 | L5: =IF(10>'WD40_Inputs_original'!B17+0,'WD40_Inputs_original'!B16+0,'WD40_Inputs_original'!B16+0-((('WD40_Inputs_original'!B16+0-'WD40_Inputs_original'!B15+0)/'WD40_Inputs_original'!B17+0)*('WD40_Inputs_original'!B17+0-10))) -> 0.17106812 | M5: =L5 -> 0.17106812
A6: Adjusted EBIT / USD m | B6: ='WD40_Inputs_original'!B44+0 -> 106.05967 | C6: =C5*C4 -> 111.36265 | D6: =D5*D4 -> 116.93078 | E6: =E5*E4 -> 122.77732 | F6: =F5*F4 -> 128.91619 | G6: =G5*G4 -> 135.362 | H6: =H5*H4 -> 141.45329 | I6: =I5*I4 -> 147.11142 | J6: =J5*J4 -> 152.26032 | ... L6: =L5*L4 -> 160.74883 | M6: =L5*M4 -> 164.76755
A7: Tax rate | B7: ='WD40_Inputs_original'!B11+0 -> 0.22200028 | C7: ='WD40_Inputs_original'!B11+0 -> 0.22200028 | D7: ='WD40_Inputs_original'!B11+0 -> 0.22200028 | E7: ='WD40_Inputs_original'!B11+0 -> 0.22200028 | F7: ='WD40_Inputs_original'!B11+0 -> 0.22200028 | G7: ='WD40_Inputs_original'!B11+0 -> 0.22200028 | H7: =G7+(('WD40_Inputs_original'!B46+0-'WD40_Inputs_original'!B11+0)/5) -> 0.22760022 | I7: =H7+(('WD40_Inputs_original'!B46+0-'WD40_Inputs_original'!B11+0)/5) -> 0.23320017 | J7: =I7+(('WD40_Inputs_original'!B46+0-'WD40_Inputs_original'!B11+0)/5) -> 0.23880011 | K7: =J7+(('WD40_Inputs_original'!B46+0-'WD40_Inputs_original'!B11+0)/5) -> 0.24440006 | L7: =K7+(('WD40_Inputs_original'!B46+0-'WD40_Inputs_original'!B11+0)/5) -> 0.25 | M7: ='WD40_Inputs_original'!B46+0 -> 0.25
A8: Opening NOL / USD m | C8: =B12 -> 0 | D8: =C12 -> 0 | E8: =D12 -> 0 | F8: =E12 -> 0 | G8: =F12 -> 0 | H8: =G12 -> 0 | I8: =H12 -> 0 | J8: =I12 -> 0 | ... M8: =L12 -> 0
A9: NOPAT / USD m | B9: =IF(B6>0,(B6*(1-B7)),B6) -> 82.514391 | C9: =IF(C6>0,IF(C6<B12,C6,C6-((C6-B12)*C7)),C6) -> 86.640111 | D9: =IF(D6>0,IF(D6<C12,D6,D6-((D6-C12)*D7)),D6) -> 90.972117 | E9: =IF(E6>0,IF(E6<D12,E6,E6-((E6-D12)*E7)),E6) -> 95.520722 | F9: =IF(F6>0,IF(F6<E12,F6,F6-((F6-E12)*F7)),F6) -> 100.29676 | G9: =IF(G6>0,IF(G6<F12,G6,G6-((G6-F12)*G7)),G6) -> 105.3116 | H9: =IF(H6>0,IF(H6<G12,H6,H6-((H6-G12)*H7)),H6) -> 109.25849 | I9: =IF(I6>0,IF(I6<H12,I6,I6-((I6-H12)*I7)),I6) -> 112.80501 | J9: =IF(J6>0,IF(J6<I12,J6,J6-((J6-I12)*J7)),J6) -> 115.90054 | ... L9: =IF(L6>0,IF(L6<K12,L6,L6-((L6-K12)*L7)),L6) -> 120.56162 | M9: =M6*(1-M7) -> 123.57566
A10: Reinvestment / USD m | C10: =IF('WD40_Inputs_original'!B30+0=1,IF('WD40_Inputs_original'!B31+0=0,((C4-B4)/C20),IF('WD40_Inputs_original'!B31+0=2,((E4-D4)/C20),IF('WD40_Inputs_original'!B31+0=3,((F4-E4)/C20),((D4-C4)/C20)))),((D4-C4)/C20)) -> 16.274606 | D10: =IF('WD40_Inputs_original'!B30+0=1,IF('WD40_Inputs_original'!B31+0=0,((D4-C4)/D20),IF('WD40_Inputs_original'!B31+0=2,((F4-E4)/D20),IF('WD40_Inputs_original'!B31+0=3,((G4-F4)/D20),((E4-D4)/D20)))),((E4-D4)/D20)) -> 17.088337 | E10: =IF('WD40_Inputs_original'!B30+0=1,IF('WD40_Inputs_original'!B31+0=0,((E4-D4)/E20),IF('WD40_Inputs_original'!B31+0=2,((G4-F4)/E20),IF('WD40_Inputs_original'!B31+0=3,((H4-G4)/E20),((F4-E4)/E20)))),((F4-E4)/E20)) -> 17.942753 | F10: =IF('WD40_Inputs_original'!B30+0=1,IF('WD40_Inputs_original'!B31+0=0,((F4-E4)/F20),IF('WD40_Inputs_original'!B31+0=2,((H4-G4)/F20),IF('WD40_Inputs_original'!B31+0=3,((I4-H4)/F20),((G4-F4)/F20)))),((G4-F4)/F20)) -> 18.839891 | G10: =IF('WD40_Inputs_original'!B30+0=1,IF('WD40_Inputs_original'!B31+0=0,((G4-F4)/G20),IF('WD40_Inputs_original'!B31+0=2,((I4-H4)/G20),IF('WD40_Inputs_original'!B31+0=3,((J4-I4)/G20),((H4-G4)/G20)))),((H4-G4)/G20)) -> 17.803697 | H10: =IF('WD40_Inputs_original'!B30+0=1,IF('WD40_Inputs_original'!B31+0=0,((H4-G4)/H20),IF('WD40_Inputs_original'!B31+0=2,((J4-I4)/H20),IF('WD40_Inputs_original'!B31+0=3,((K4-J4)/H20),((I4-H4)/H20)))),((I4-H4)/H20)) -> 16.537656 | I10: =IF('WD40_Inputs_original'!B30+0=1,IF('WD40_Inputs_original'!B31+0=0,((I4-H4)/I20),IF('WD40_Inputs_original'!B31+0=2,((K4-J4)/I20),IF('WD40_Inputs_original'!B31+0=3,((L4-K4)/I20),((J4-I4)/I20)))),((J4-I4)/I20)) -> 15.049267 | J10: =IF('WD40_Inputs_original'!B30+0=1,IF('WD40_Inputs_original'!B31+0=0,((J4-I4)/J20),IF('WD40_Inputs_original'!B31+0=2,((L4-K4)/J20),IF('WD40_Inputs_original'!B31+0=3,((M4-L4)/J20),((K4-J4)/J20)))),((K4-J4)/J20)) -> 13.35085 | K10: =IF('WD40_Inputs_original'!B30+0=1,IF('WD40_Inputs_original'!B31+0=0,((K4-J4)/K20),IF('WD40_Inputs_original'!B31+0=2,((M4-L4)/K20),IF('WD40_Inputs_original'!B31+0=3,((M4*M3)/K20),((L4-K4)/K20)))),((L4-K4)/K20)) -> 11.45948 | L10: =IF('WD40_Inputs_original'!B30+0=1,IF('WD40_Inputs_original'!B31+0=0,((L4-K4)/L20),IF('WD40_Inputs_original'!B31+0=2,((M4*M3)/L20),IF('WD40_Inputs_original'!B31+0=3,((K10*(1+M3)*L20)/L20),((M4-L4)/L20)))),((M4-L4)/L20)) -> 11.745967 | M10: =B30*M9 -> 38.617395
A11: FCFF / USD m | C11: =C9-C10 -> 70.365505 | D11: =D9-D10 -> 73.88378 | E11: =E9-E10 -> 77.577969 | F11: =F9-F10 -> 81.456867 | G11: =G9-G10 -> 87.507899 | H11: =H9-H10 -> 92.720831 | I11: =I9-I10 -> 97.755744 | J11: =J9-J10 -> 102.54969 | ... M11: =M9-M10 -> 84.958269
A12: Closing NOL / USD m | B12: ='WD40_Inputs_original'!B28+0 -> 0 | C12: =IF(C6<0,(B12-C6),IF(B12>C6,(B12-C6),0)) -> 0 | D12: =IF(D6<0,(C12-D6),IF(C12>D6,(C12-D6),0)) -> 0 | E12: =IF(E6<0,(D12-E6),IF(D12>E6,(D12-E6),0)) -> 0 | F12: =IF(F6<0,(E12-F6),IF(E12>F6,(E12-F6),0)) -> 0 | G12: =IF(G6<0,(F12-G6),IF(F12>G6,(F12-G6),0)) -> 0 | H12: =IF(H6<0,(G12-H6),IF(G12>H6,(G12-H6),0)) -> 0 | I12: =IF(I6<0,(H12-I6),IF(H12>I6,(H12-I6),0)) -> 0 | J12: =IF(J6<0,(I12-J6),IF(I12>J6,(I12-J6),0)) -> 0 | ... M12: =IF(M6<0,(L12-M6),IF(L12>M6,(L12-M6),0)) -> 0
A13: WACC | C13: ='WD40_Inputs_original'!B20+0 -> 0.09 | D13: ='WD40_Inputs_original'!B20+0 -> 0.09 | E13: ='WD40_Inputs_original'!B20+0 -> 0.09 | F13: ='WD40_Inputs_original'!B20+0 -> 0.09 | G13: ='WD40_Inputs_original'!B20+0 -> 0.09 | H13: =G13-(('WD40_Inputs_original'!B20+0-'WD40_Inputs_original'!B21+0)/5) -> 0.088 | I13: =H13-(('WD40_Inputs_original'!B20+0-'WD40_Inputs_original'!B21+0)/5) -> 0.086 | J13: =I13-(('WD40_Inputs_original'!B20+0-'WD40_Inputs_original'!B21+0)/5) -> 0.084 | K13: =J13-(('WD40_Inputs_original'!B20+0-'WD40_Inputs_original'!B21+0)/5) -> 0.082 | L13: =K13-(('WD40_Inputs_original'!B20+0-'WD40_Inputs_original'!B21+0)/5) -> 0.08 | M13: ='WD40_Inputs_original'!B21+0 -> 0.08
A14: Cumulative discount factor | C14: =1*(1/(1+C13)) -> 0.91743119 | D14: =C14*(1/(1+D13)) -> 0.84167999 | E14: =D14*(1/(1+E13)) -> 0.77218348 | F14: =E14*(1/(1+F13)) -> 0.70842521 | G14: =F14*(1/(1+G13)) -> 0.64993139 | H14: =G14*(1/(1+H13)) -> 0.59736341 | I14: =H14*(1/(1+I13)) -> 0.55005839 | J14: =I14*(1/(1+J13)) -> 0.50743393 | K14: =J14*(1/(1+K13)) -> 0.46897776 | L14: =K14*(1/(1+L13)) -> 0.43423867
A15: PV FCFF / USD m | C15: =C11*C14 -> 64.555509 | D15: =D11*D14 -> 62.186499 | E15: =E11*E14 -> 59.904426 | F15: =F11*F14 -> 57.706099 | G15: =G11*G14 -> 56.87413 | H15: =H11*H14 -> 55.388032 | I15: =I11*I14 -> 53.771367 | J15: =J11*J14 -> 52.037191 | ... L15: =L11*L14 -> 47.251965
A16: Opening invested capital / USD m | C16: =B17 -> 313.437 | D16: =C17 -> 329.71161 | E16: =D17 -> 346.79994 | F16: =E17 -> 364.7427 | G16: =F17 -> 383.58259 | H16: =G17 -> 401.38628 | I16: =H17 -> 417.92394 | J16: =I17 -> 432.97321 | ... L16: =K17 -> 457.78354
A17: Closing invested capital / USD m | B17: ='WD40_Inputs_original'!B45+0 -> 313.437 | C17: =B17+C10 -> 329.71161 | D17: =C17+D10 -> 346.79994 | E17: =D17+E10 -> 364.7427 | F17: =E17+F10 -> 383.58259 | G17: =F17+G10 -> 401.38628 | H17: =G17+H10 -> 417.92394 | I17: =H17+I10 -> 432.97321 | J17: =I17+J10 -> 446.32406 | ... L17: =K17+L10 -> 469.5295
A18: Economic profit / USD m | C18: =C9-(C13*B17) -> 58.430781 | D18: =D9-(D13*C17) -> 61.298072 | E18: =E9-(E13*D17) -> 64.308728 | F18: =F9-(F13*E17) -> 67.469916 | G18: =G9-(G13*F17) -> 70.789164 | H18: =H9-(H13*G17) -> 73.936495 | I18: =I9-(I13*H17) -> 76.863552 | J18: =J9-(J13*I17) -> 79.530788 | ... L18: =L9-(L13*K17) -> 83.93894
A19: PV economic profit / USD m | C19: =C18*C14 -> 53.606221 | D19: =D18*D14 -> 51.593361 | E19: =E18*E14 -> 49.658137 | F19: =F18*F14 -> 47.797389 | G19: =G18*G14 -> 46.008099 | H19: =H18*H14 -> 44.166956 | I19: =I18*I14 -> 42.279442 | J19: =J18*J14 -> 40.356621 | ... L19: =L18*L14 -> 36.449533
A20: Sales to capital | C20: ='WD40_Inputs_original'!B18+0 -> 2 | D20: ='WD40_Inputs_original'!B18+0 -> 2 | E20: ='WD40_Inputs_original'!B18+0 -> 2 | F20: ='WD40_Inputs_original'!B18+0 -> 2 | G20: ='WD40_Inputs_original'!B18+0 -> 2 | H20: ='WD40_Inputs_original'!B19+0 -> 2 | I20: ='WD40_Inputs_original'!B19+0 -> 2 | J20: ='WD40_Inputs_original'!B19+0 -> 2 | K20: ='WD40_Inputs_original'!B19+0 -> 2 | L20: ='WD40_Inputs_original'!B19+0 -> 2
A21: Terminal value / USD m | B21: =M11/(M13-M3) -> 1544.6958
A22: PV terminal value / USD m | B22: =B21*L14 -> 670.76664
A23: PV forecast FCFF / USD m | B23: =SUM(C15:L15) -> 559.87453
A24: Undistressed operating value / USD m | B24: =B22+B23 -> 1230.6412
A25: Distress proceeds / USD m | B25: =IF('WD40_Inputs_original'!B34+0=1,(('WD40_Inputs_original'!B4+0+'WD40_Inputs_original'!B5+0)*'WD40_Inputs_original'!B33+0),(B24*'WD40_Inputs_original'!B33+0)) -> 615.32058
A26: Operating value / USD m | B26: =(B24*(1-'WD40_Inputs_original'!B32+0))+(B25*'WD40_Inputs_original'!B32+0) -> 1230.6412
A27: Equity value / USD m | B27: =B26-'WD40_Inputs_original'!B5+0-'WD40_Inputs_original'!B8+0+'WD40_Inputs_original'!B48+0+'WD40_Inputs_original'!B7+0 -> 1201.7762
A28: Value per share / USD | B28: =IF('WD40_Inputs_original'!B21+0>'WD40_Inputs_original'!B22+0,IF('WD40_Inputs_original'!B20+0>0,IF('WD40_Inputs_original'!B9+0>0,IF('WD40_Inputs_original'!B18+0>0,IF('WD40_Inputs_original'!B19+0>0,IF(IF('WD40_Inputs_original'!B23+0=1,IF('WD40_Inputs_original'!B24+0>0,1,0),1)=1,IF(IF('WD40_Inputs_original'!B23+0=1,IF('WD40_Inputs_original'!B24+0>='WD40_Inputs_original'!B22+0,1,0),1)=1,B27/'WD40_Inputs_original'!B9+0,"Blocked: terminal reinvestment exceeds NOPAT"),"Blocked: active terminal ROIC must be positive"),"Blocked: years 6-10 sales to capital must be positive"),"Blocked: years 1-5 sales to capital must be positive"),"Blocked: shares must be positive"),"Blocked: starting WACC must be positive"),"Blocked: terminal WACC must exceed growth") -> 88.150296
A29: Terminal value share | B29: =B22/B24 -> 0.54505461
A30: Terminal reinvestment rate | B30: =IF(M3>0,(M3/IF('WD40_Inputs_original'!B23+0=1,'WD40_Inputs_original'!B24+0,L13)),0) -> 0.3125
A31: EVA recurring terminal value / USD m | B31: =IF(M3>0,((M9*(1-(M13/IF('WD40_Inputs_original'!B23+0=1,'WD40_Inputs_original'!B24+0,L13))))/(M13-M3)),(M9/(M13-M3))) -> -4.9889653e-13
A32: EVA terminal capital transition / USD m | B32: =IF(M3>0,((M9/IF('WD40_Inputs_original'!B23+0=1,'WD40_Inputs_original'!B24+0,L13))-L17),(0-L17)) -> 1075.1663
A33: EVA terminal value / USD m | B33: =B31+B32 -> 1075.1663
A34: EVA operating value / USD m | B34: =B17+SUM(C19:L19)+(B33*L14) -> 1230.6412
A35: EVA minus DCF / USD m | B35: =B34-B24 -> 2.2737368e-13

Sheet WD40_Inputs_bear
A1: WD40_Inputs_bear | B1: Value
A2: Revenue FY2025 / USD m | B2: ='WD40_Regions_bear'!E2+0 -> 619.985
A3: Reported EBIT FY2025 / USD m | B3: 103.793
A4: Adjusted book equity / USD m | B4: 268.472
A5: Interest-bearing debt / USD m | B5: 86.995
A6: Cash / USD m | B6: 58.13
A7: Nonoperating assets / USD m | B7: 0
A8: Minority interests / USD m | B8: 0
A9: Valuation dilution proxy / million shares | B9: 13.633263
A10: Historical reference price / USD per share | B10: 216.04
A11: Normalized starting tax rate | B11: 0.22200028
A12: Terminal tax rate | B12: 0.25
A13: Revenue growth year 1 | B13: ='WD40_Regions_bear'!E47+0 -> 0.028936942
A14: Revenue growth years 2-5 | B14: ='WD40_Regions_bear'!E48+0 -> 0.029813668
A15: Adjusted EBIT margin year 1 | B15: =B44/B2 -> 0.17106812
A16: Target adjusted EBIT margin | B16: =B15+0 -> 0.17106812
A17: Margin convergence year | B17: 5
A18: Sales to capital years 1-5 | B18: 2
A19: Sales to capital years 6-10 | B19: =B18+0 -> 2
A20: WACC years 1-5 | B20: 0.09
A21: Terminal WACC | B21: 0.08
A22: Terminal growth | B22: 0.025
A23: Use explicit terminal ROIC / 1=yes | B23: 0
A24: Explicit terminal ROIC | B24: 0.15
A25: Current R&D / USD m | B25: 8.7
A26: R&D amortization life / years | B26: 3
A27: Capitalize R&D / 1=yes | B27: 1
A28: Starting NOL / USD m | B28: 0
A29: Hold starting tax rate / 1=yes | B29: 0
A30: Override reinvestment timing / 1=yes | B30: 0
A31: Reinvestment growth lead / years | B31: 1
... A41: R&D 4 years prior / USD m | B41: 5.6
A42: R&D amortization / USD m | B42: =0+IF(1<=B26,(B38/B26),0)+IF(2<=B26,(B39/B26),0)+IF(3<=B26,(B40/B26),0)+IF(4<=B26,(B41/B26),0) -> 6.4333333
A43: Unamortized R&D asset / USD m | B43: =B25+IF(1<B26,(B38*((B26-1)/B26)),0)+IF(2<B26,(B39*((B26-2)/B26)),0)+IF(3<B26,(B40*((B26-3)/B26)),0)+IF(4<B26,(B41*((B26-4)/B26)),0) -> 16.1
A44: R&D-adjusted base EBIT / USD m | B44: =B3+IF(B27=1,(B25-B42),0) -> 106.05967
A45: Base invested capital / USD m | B45: =B4+B5-B6+IF(B27=1,B43,0) -> 313.437
A46: Effective terminal tax rate | B46: =IF(B29=1,B11,B12) -> 0.25
A47: Effective terminal ROIC | B47: =IF(B23=1,B24,B21) -> 0.08
A48: Cash after explicit haircut / USD m | B48: =B6-IF(B37=1,(B35*(B12-B36)),0) -> 58.13

Sheet WD40_DCF_bear
A1: WD40_DCF_bear | B1: Base | C1: Y1 | D1: Y2 | E1: Y3 | F1: Y4 | G1: Y5 | H1: Y6 | I1: Y7 | J1: Y8 | K1: Y9 | L1: Y10 | M1: Terminal
A2: Year | B2: 0 | C2: 1 | D2: 2 | E2: 3 | F2: 4 | G2: 5 | H2: 6 | I2: 7 | J2: 8 | K2: 9 | L2: 10 | M2: 11
A3: Revenue growth | C3: ='WD40_Inputs_bear'!B13+0 -> 0.028936942 | D3: ='WD40_Inputs_bear'!B14+0 -> 0.029813668 | E3: ='WD40_Inputs_bear'!B14+0 -> 0.029813668 | F3: ='WD40_Inputs_bear'!B14+0 -> 0.029813668 | G3: ='WD40_Inputs_bear'!B14+0 -> 0.029813668 | H3: ='WD40_Inputs_bear'!B14+0-((('WD40_Inputs_bear'!B14+0-'WD40_Inputs_bear'!B22+0)/5)*1) -> 0.028850934 | I3: ='WD40_Inputs_bear'!B14+0-((('WD40_Inputs_bear'!B14+0-'WD40_Inputs_bear'!B22+0)/5)*2) -> 0.027888201 | J3: ='WD40_Inputs_bear'!B14+0-((('WD40_Inputs_bear'!B14+0-'WD40_Inputs_bear'!B22+0)/5)*3) -> 0.026925467 | K3: ='WD40_Inputs_bear'!B14+0-((('WD40_Inputs_bear'!B14+0-'WD40_Inputs_bear'!B22+0)/5)*4) -> 0.025962734 | L3: ='WD40_Inputs_bear'!B14+0-((('WD40_Inputs_bear'!B14+0-'WD40_Inputs_bear'!B22+0)/5)*5) -> 0.025 | M3: ='WD40_Inputs_bear'!B22+0 -> 0.025
A4: Revenue / USD m | B4: ='WD40_Inputs_bear'!B2+0 -> 619.985 | C4: =B4*(1+C3) -> 637.92547 | D4: =C4*(1+D3) -> 656.94437 | E4: =D4*(1+E3) -> 676.53029 | F4: =E4*(1+F3) -> 696.70014 | G4: =F4*(1+G3) -> 717.47133 | H4: =G4*(1+H3) -> 738.17104 | I4: =H4*(1+I3) -> 758.75731 | J4: =I4*(1+J3) -> 779.1872 | ... M4: =L4*(1+M3) -> 839.88752
A5: Adjusted EBIT margin | B5: =B6/B4 -> 0.17106812 | C5: ='WD40_Inputs_bear'!B15+0 -> 0.17106812 | D5: =IF(2>'WD40_Inputs_bear'!B17+0,'WD40_Inputs_bear'!B16+0,'WD40_Inputs_bear'!B16+0-((('WD40_Inputs_bear'!B16+0-'WD40_Inputs_bear'!B15+0)/'WD40_Inputs_bear'!B17+0)*('WD40_Inputs_bear'!B17+0-2))) -> 0.17106812 | E5: =IF(3>'WD40_Inputs_bear'!B17+0,'WD40_Inputs_bear'!B16+0,'WD40_Inputs_bear'!B16+0-((('WD40_Inputs_bear'!B16+0-'WD40_Inputs_bear'!B15+0)/'WD40_Inputs_bear'!B17+0)*('WD40_Inputs_bear'!B17+0-3))) -> 0.17106812 | F5: =IF(4>'WD40_Inputs_bear'!B17+0,'WD40_Inputs_bear'!B16+0,'WD40_Inputs_bear'!B16+0-((('WD40_Inputs_bear'!B16+0-'WD40_Inputs_bear'!B15+0)/'WD40_Inputs_bear'!B17+0)*('WD40_Inputs_bear'!B17+0-4))) -> 0.17106812 | G5: =IF(5>'WD40_Inputs_bear'!B17+0,'WD40_Inputs_bear'!B16+0,'WD40_Inputs_bear'!B16+0-((('WD40_Inputs_bear'!B16+0-'WD40_Inputs_bear'!B15+0)/'WD40_Inputs_bear'!B17+0)*('WD40_Inputs_bear'!B17+0-5))) -> 0.17106812 | H5: =IF(6>'WD40_Inputs_bear'!B17+0,'WD40_Inputs_bear'!B16+0,'WD40_Inputs_bear'!B16+0-((('WD40_Inputs_bear'!B16+0-'WD40_Inputs_bear'!B15+0)/'WD40_Inputs_bear'!B17+0)*('WD40_Inputs_bear'!B17+0-6))) -> 0.17106812 | I5: =IF(7>'WD40_Inputs_bear'!B17+0,'WD40_Inputs_bear'!B16+0,'WD40_Inputs_bear'!B16+0-((('WD40_Inputs_bear'!B16+0-'WD40_Inputs_bear'!B15+0)/'WD40_Inputs_bear'!B17+0)*('WD40_Inputs_bear'!B17+0-7))) -> 0.17106812 | J5: =IF(8>'WD40_Inputs_bear'!B17+0,'WD40_Inputs_bear'!B16+0,'WD40_Inputs_bear'!B16+0-((('WD40_Inputs_bear'!B16+0-'WD40_Inputs_bear'!B15+0)/'WD40_Inputs_bear'!B17+0)*('WD40_Inputs_bear'!B17+0-8))) -> 0.17106812 | K5: =IF(9>'WD40_Inputs_bear'!B17+0,'WD40_Inputs_bear'!B16+0,'WD40_Inputs_bear'!B16+0-((('WD40_Inputs_bear'!B16+0-'WD40_Inputs_bear'!B15+0)/'WD40_Inputs_bear'!B17+0)*('WD40_Inputs_bear'!B17+0-9))) -> 0.17106812 | L5: =IF(10>'WD40_Inputs_bear'!B17+0,'WD40_Inputs_bear'!B16+0,'WD40_Inputs_bear'!B16+0-((('WD40_Inputs_bear'!B16+0-'WD40_Inputs_bear'!B15+0)/'WD40_Inputs_bear'!B17+0)*('WD40_Inputs_bear'!B17+0-10))) -> 0.17106812 | M5: =L5 -> 0.17106812
A6: Adjusted EBIT / USD m | B6: ='WD40_Inputs_bear'!B44+0 -> 106.05967 | C6: =C5*C4 -> 109.12871 | D6: =D5*D4 -> 112.38224 | E6: =E5*E4 -> 115.73276 | F6: =F5*F4 -> 119.18318 | G6: =G5*G4 -> 122.73647 | H6: =H5*H4 -> 126.27753 | I6: =I5*I4 -> 129.79918 | J6: =J5*J4 -> 133.29409 | ... L6: =L5*L4 -> 140.17364 | M6: =L5*M4 -> 143.67798
A7: Tax rate | B7: ='WD40_Inputs_bear'!B11+0 -> 0.22200028 | C7: ='WD40_Inputs_bear'!B11+0 -> 0.22200028 | D7: ='WD40_Inputs_bear'!B11+0 -> 0.22200028 | E7: ='WD40_Inputs_bear'!B11+0 -> 0.22200028 | F7: ='WD40_Inputs_bear'!B11+0 -> 0.22200028 | G7: ='WD40_Inputs_bear'!B11+0 -> 0.22200028 | H7: =G7+(('WD40_Inputs_bear'!B46+0-'WD40_Inputs_bear'!B11+0)/5) -> 0.22760022 | I7: =H7+(('WD40_Inputs_bear'!B46+0-'WD40_Inputs_bear'!B11+0)/5) -> 0.23320017 | J7: =I7+(('WD40_Inputs_bear'!B46+0-'WD40_Inputs_bear'!B11+0)/5) -> 0.23880011 | K7: =J7+(('WD40_Inputs_bear'!B46+0-'WD40_Inputs_bear'!B11+0)/5) -> 0.24440006 | L7: =K7+(('WD40_Inputs_bear'!B46+0-'WD40_Inputs_bear'!B11+0)/5) -> 0.25 | M7: ='WD40_Inputs_bear'!B46+0 -> 0.25
A8: Opening NOL / USD m | C8: =B12 -> 0 | D8: =C12 -> 0 | E8: =D12 -> 0 | F8: =E12 -> 0 | G8: =F12 -> 0 | H8: =G12 -> 0 | I8: =H12 -> 0 | J8: =I12 -> 0 | ... M8: =L12 -> 0
A9: NOPAT / USD m | B9: =IF(B6>0,(B6*(1-B7)),B6) -> 82.514391 | C9: =IF(C6>0,IF(C6<B12,C6,C6-((C6-B12)*C7)),C6) -> 84.902106 | D9: =IF(D6>0,IF(D6<C12,D6,D6-((D6-C12)*D7)),D6) -> 87.433349 | E9: =IF(E6>0,IF(E6<D12,E6,E6-((E6-D12)*E7)),E6) -> 90.040058 | F9: =IF(F6>0,IF(F6<E12,F6,F6-((F6-E12)*F7)),F6) -> 92.724482 | G9: =IF(G6>0,IF(G6<F12,G6,G6-((G6-F12)*G7)),G6) -> 95.488939 | H9: =IF(H6>0,IF(H6<G12,H6,H6-((H6-G12)*H7)),H6) -> 97.536737 | I9: =IF(I6>0,IF(I6<H12,I6,I6-((I6-H12)*I7)),I6) -> 99.529993 | J9: =IF(J6>0,IF(J6<I12,J6,J6-((J6-I12)*J7)),J6) -> 101.46344 | ... L9: =IF(L6>0,IF(L6<K12,L6,L6-((L6-K12)*L7)),L6) -> 105.13023 | M9: =M6*(1-M7) -> 107.75848
A10: Reinvestment / USD m | C10: =IF('WD40_Inputs_bear'!B30+0=1,IF('WD40_Inputs_bear'!B31+0=0,((C4-B4)/C20),IF('WD40_Inputs_bear'!B31+0=2,((E4-D4)/C20),IF('WD40_Inputs_bear'!B31+0=3,((F4-E4)/C20),((D4-C4)/C20)))),((D4-C4)/C20)) -> 9.5094491 | D10: =IF('WD40_Inputs_bear'!B30+0=1,IF('WD40_Inputs_bear'!B31+0=0,((D4-C4)/D20),IF('WD40_Inputs_bear'!B31+0=2,((F4-E4)/D20),IF('WD40_Inputs_bear'!B31+0=3,((G4-F4)/D20),((E4-D4)/D20)))),((E4-D4)/D20)) -> 9.7929607 | E10: =IF('WD40_Inputs_bear'!B30+0=1,IF('WD40_Inputs_bear'!B31+0=0,((E4-D4)/E20),IF('WD40_Inputs_bear'!B31+0=2,((G4-F4)/E20),IF('WD40_Inputs_bear'!B31+0=3,((H4-G4)/E20),((F4-E4)/E20)))),((F4-E4)/E20)) -> 10.084925 | F10: =IF('WD40_Inputs_bear'!B30+0=1,IF('WD40_Inputs_bear'!B31+0=0,((F4-E4)/F20),IF('WD40_Inputs_bear'!B31+0=2,((H4-G4)/F20),IF('WD40_Inputs_bear'!B31+0=3,((I4-H4)/F20),((G4-F4)/F20)))),((G4-F4)/F20)) -> 10.385593 | G10: =IF('WD40_Inputs_bear'!B30+0=1,IF('WD40_Inputs_bear'!B31+0=0,((G4-F4)/G20),IF('WD40_Inputs_bear'!B31+0=2,((I4-H4)/G20),IF('WD40_Inputs_bear'!B31+0=3,((J4-I4)/G20),((H4-G4)/G20)))),((H4-G4)/G20)) -> 10.349859 | H10: =IF('WD40_Inputs_bear'!B30+0=1,IF('WD40_Inputs_bear'!B31+0=0,((H4-G4)/H20),IF('WD40_Inputs_bear'!B31+0=2,((J4-I4)/H20),IF('WD40_Inputs_bear'!B31+0=3,((K4-J4)/H20),((I4-H4)/H20)))),((I4-H4)/H20)) -> 10.293131 | I10: =IF('WD40_Inputs_bear'!B30+0=1,IF('WD40_Inputs_bear'!B31+0=0,((I4-H4)/I20),IF('WD40_Inputs_bear'!B31+0=2,((K4-J4)/I20),IF('WD40_Inputs_bear'!B31+0=3,((L4-K4)/I20),((J4-I4)/I20)))),((J4-I4)/I20)) -> 10.214947 | J10: =IF('WD40_Inputs_bear'!B30+0=1,IF('WD40_Inputs_bear'!B31+0=0,((J4-I4)/J20),IF('WD40_Inputs_bear'!B31+0=2,((L4-K4)/J20),IF('WD40_Inputs_bear'!B31+0=3,((M4-L4)/J20),((K4-J4)/J20)))),((K4-J4)/J20)) -> 10.114915 | K10: =IF('WD40_Inputs_bear'!B30+0=1,IF('WD40_Inputs_bear'!B31+0=0,((K4-J4)/K20),IF('WD40_Inputs_bear'!B31+0=2,((M4-L4)/K20),IF('WD40_Inputs_bear'!B31+0=3,((M4*M3)/K20),((L4-K4)/K20)))),((L4-K4)/K20)) -> 9.9927129 | L10: =IF('WD40_Inputs_bear'!B30+0=1,IF('WD40_Inputs_bear'!B31+0=0,((L4-K4)/L20),IF('WD40_Inputs_bear'!B31+0=2,((M4*M3)/L20),IF('WD40_Inputs_bear'!B31+0=3,((K10*(1+M3)*L20)/L20),((M4-L4)/L20)))),((M4-L4)/L20)) -> 10.242531 | M10: =B30*M9 -> 33.674526
A11: FCFF / USD m | C11: =C9-C10 -> 75.392656 | D11: =D9-D10 -> 77.640388 | E11: =E9-E10 -> 79.955133 | F11: =F9-F10 -> 82.338889 | G11: =G9-G10 -> 85.13908 | H11: =H9-H10 -> 87.243606 | I11: =I9-I10 -> 89.315045 | J11: =J9-J10 -> 91.34853 | ... M11: =M9-M10 -> 74.083957
A12: Closing NOL / USD m | B12: ='WD40_Inputs_bear'!B28+0 -> 0 | C12: =IF(C6<0,(B12-C6),IF(B12>C6,(B12-C6),0)) -> 0 | D12: =IF(D6<0,(C12-D6),IF(C12>D6,(C12-D6),0)) -> 0 | E12: =IF(E6<0,(D12-E6),IF(D12>E6,(D12-E6),0)) -> 0 | F12: =IF(F6<0,(E12-F6),IF(E12>F6,(E12-F6),0)) -> 0 | G12: =IF(G6<0,(F12-G6),IF(F12>G6,(F12-G6),0)) -> 0 | H12: =IF(H6<0,(G12-H6),IF(G12>H6,(G12-H6),0)) -> 0 | I12: =IF(I6<0,(H12-I6),IF(H12>I6,(H12-I6),0)) -> 0 | J12: =IF(J6<0,(I12-J6),IF(I12>J6,(I12-J6),0)) -> 0 | ... M12: =IF(M6<0,(L12-M6),IF(L12>M6,(L12-M6),0)) -> 0
A13: WACC | C13: ='WD40_Inputs_bear'!B20+0 -> 0.09 | D13: ='WD40_Inputs_bear'!B20+0 -> 0.09 | E13: ='WD40_Inputs_bear'!B20+0 -> 0.09 | F13: ='WD40_Inputs_bear'!B20+0 -> 0.09 | G13: ='WD40_Inputs_bear'!B20+0 -> 0.09 | H13: =G13-(('WD40_Inputs_bear'!B20+0-'WD40_Inputs_bear'!B21+0)/5) -> 0.088 | I13: =H13-(('WD40_Inputs_bear'!B20+0-'WD40_Inputs_bear'!B21+0)/5) -> 0.086 | J13: =I13-(('WD40_Inputs_bear'!B20+0-'WD40_Inputs_bear'!B21+0)/5) -> 0.084 | K13: =J13-(('WD40_Inputs_bear'!B20+0-'WD40_Inputs_bear'!B21+0)/5) -> 0.082 | L13: =K13-(('WD40_Inputs_bear'!B20+0-'WD40_Inputs_bear'!B21+0)/5) -> 0.08 | M13: ='WD40_Inputs_bear'!B21+0 -> 0.08
A14: Cumulative discount factor | C14: =1*(1/(1+C13)) -> 0.91743119 | D14: =C14*(1/(1+D13)) -> 0.84167999 | E14: =D14*(1/(1+E13)) -> 0.77218348 | F14: =E14*(1/(1+F13)) -> 0.70842521 | G14: =F14*(1/(1+G13)) -> 0.64993139 | H14: =G14*(1/(1+H13)) -> 0.59736341 | I14: =H14*(1/(1+I13)) -> 0.55005839 | J14: =I14*(1/(1+J13)) -> 0.50743393 | K14: =J14*(1/(1+K13)) -> 0.46897776 | L14: =K14*(1/(1+L13)) -> 0.43423867
A15: PV FCFF / USD m | C15: =C11*C14 -> 69.167575 | D15: =D11*D14 -> 65.348361 | E15: =E11*E14 -> 61.740033 | F15: =F11*F14 -> 58.330945 | G15: =G11*G14 -> 55.33456 | H15: =H11*H14 -> 52.116138 | I15: =I11*I14 -> 49.12849 | J15: =J11*J14 -> 46.353344 | ... L15: =L11*L14 -> 41.203906
A16: Opening invested capital / USD m | C16: =B17 -> 313.437 | D16: =C17 -> 322.94645 | E16: =D17 -> 332.73941 | F16: =E17 -> 342.82433 | G16: =F17 -> 353.20993 | H16: =G17 -> 363.55979 | I16: =H17 -> 373.85292 | J16: =I17 -> 384.06787 | ... L16: =K17 -> 404.17549
A17: Closing invested capital / USD m | B17: ='WD40_Inputs_bear'!B45+0 -> 313.437 | C17: =B17+C10 -> 322.94645 | D17: =C17+D10 -> 332.73941 | E17: =D17+E10 -> 342.82433 | F17: =E17+F10 -> 353.20993 | G17: =F17+G10 -> 363.55979 | H17: =G17+H10 -> 373.85292 | I17: =H17+I10 -> 384.06787 | J17: =I17+J10 -> 394.18278 | ... L17: =K17+L10 -> 414.41802
A18: Economic profit / USD m | C18: =C9-(C13*B17) -> 56.692776 | D18: =D9-(D13*C17) -> 58.368168 | E18: =E9-(E13*D17) -> 60.093511 | F18: =F9-(F13*E17) -> 61.870292 | G18: =G9-(G13*F17) -> 63.700045 | H18: =H9-(H13*G17) -> 65.543476 | I18: =I9-(I13*H17) -> 67.378642 | J18: =J9-(J13*I17) -> 69.201744 | ... L18: =L9-(L13*K17) -> 72.796187
A19: PV economic profit / USD m | C19: =C18*C14 -> 52.011721 | D19: =D18*D14 -> 49.12732 | E19: =E18*E14 -> 46.403216 | F19: =F18*F14 -> 43.830475 | G19: =G18*G14 -> 41.400659 | H19: =H18*H14 -> 39.153274 | I19: =I18*I14 -> 37.062187 | J19: =J18*J14 -> 35.115313 | ... L19: =L18*L14 -> 31.610919
A20: Sales to capital | C20: ='WD40_Inputs_bear'!B18+0 -> 2 | D20: ='WD40_Inputs_bear'!B18+0 -> 2 | E20: ='WD40_Inputs_bear'!B18+0 -> 2 | F20: ='WD40_Inputs_bear'!B18+0 -> 2 | G20: ='WD40_Inputs_bear'!B18+0 -> 2 | H20: ='WD40_Inputs_bear'!B19+0 -> 2 | I20: ='WD40_Inputs_bear'!B19+0 -> 2 | J20: ='WD40_Inputs_bear'!B19+0 -> 2 | K20: ='WD40_Inputs_bear'!B19+0 -> 2 | L20: ='WD40_Inputs_bear'!B19+0 -> 2
A21: Terminal value / USD m | B21: =M11/(M13-M3) -> 1346.981
A22: PV terminal value / USD m | B22: =B21*L14 -> 584.91124
A23: PV forecast FCFF / USD m | B23: =SUM(C15:L15) -> 542.49735
A24: Undistressed operating value / USD m | B24: =B22+B23 -> 1127.4086
A25: Distress proceeds / USD m | B25: =IF('WD40_Inputs_bear'!B34+0=1,(('WD40_Inputs_bear'!B4+0+'WD40_Inputs_bear'!B5+0)*'WD40_Inputs_bear'!B33+0),(B24*'WD40_Inputs_bear'!B33+0)) -> 563.7043
A26: Operating value / USD m | B26: =(B24*(1-'WD40_Inputs_bear'!B32+0))+(B25*'WD40_Inputs_bear'!B32+0) -> 1127.4086
A27: Equity value / USD m | B27: =B26-'WD40_Inputs_bear'!B5+0-'WD40_Inputs_bear'!B8+0+'WD40_Inputs_bear'!B48+0+'WD40_Inputs_bear'!B7+0 -> 1098.5436
A28: Value per share / USD | B28: =IF('WD40_Inputs_bear'!B21+0>'WD40_Inputs_bear'!B22+0,IF('WD40_Inputs_bear'!B20+0>0,IF('WD40_Inputs_bear'!B9+0>0,IF('WD40_Inputs_bear'!B18+0>0,IF('WD40_Inputs_bear'!B19+0>0,IF(IF('WD40_Inputs_bear'!B23+0=1,IF('WD40_Inputs_bear'!B24+0>0,1,0),1)=1,IF(IF('WD40_Inputs_bear'!B23+0=1,IF('WD40_Inputs_bear'!B24+0>='WD40_Inputs_bear'!B22+0,1,0),1)=1,B27/'WD40_Inputs_bear'!B9+0,"Blocked: terminal reinvestment exceeds NOPAT"),"Blocked: active terminal ROIC must be positive"),"Blocked: years 6-10 sales to capital must be positive"),"Blocked: years 1-5 sales to capital must be positive"),"Blocked: shares must be positive"),"Blocked: starting WACC must be positive"),"Blocked: terminal WACC must exceed growth") -> 80.578186
A29: Terminal value share | B29: =B22/B24 -> 0.51881035
A30: Terminal reinvestment rate | B30: =IF(M3>0,(M3/IF('WD40_Inputs_bear'!B23+0=1,'WD40_Inputs_bear'!B24+0,L13)),0) -> 0.3125
A31: EVA recurring terminal value / USD m | B31: =IF(M3>0,((M9*(1-(M13/IF('WD40_Inputs_bear'!B23+0=1,'WD40_Inputs_bear'!B24+0,L13))))/(M13-M3)),(M9/(M13-M3))) -> -4.3503981e-13
A32: EVA terminal capital transition / USD m | B32: =IF(M3>0,((M9/IF('WD40_Inputs_bear'!B23+0=1,'WD40_Inputs_bear'!B24+0,L13))-L17),(0-L17)) -> 932.563
A33: EVA terminal value / USD m | B33: =B31+B32 -> 932.563
A34: EVA operating value / USD m | B34: =B17+SUM(C19:L19)+(B33*L14) -> 1127.4086
A35: EVA minus DCF / USD m | B35: =B34-B24 -> 2.2737368e-13

Sheet WD40_Inputs_base
A1: WD40_Inputs_base | B1: Value
A2: Revenue FY2025 / USD m | B2: ='WD40_Regions_base'!E2+0 -> 619.985
A3: Reported EBIT FY2025 / USD m | B3: 103.793
A4: Adjusted book equity / USD m | B4: 268.472
A5: Interest-bearing debt / USD m | B5: 86.995
A6: Cash / USD m | B6: 58.13
A7: Nonoperating assets / USD m | B7: 0
A8: Minority interests / USD m | B8: 0
A9: Valuation dilution proxy / million shares | B9: 13.633263
A10: Historical reference price / USD per share | B10: 216.04
A11: Normalized starting tax rate | B11: 0.22200028
A12: Terminal tax rate | B12: 0.25
A13: Revenue growth year 1 | B13: ='WD40_Regions_base'!E47+0 -> 0.060436204
A14: Revenue growth years 2-5 | B14: ='WD40_Regions_base'!E48+0 -> 0.061544421
A15: Adjusted EBIT margin year 1 | B15: =B44/B2 -> 0.17106812
A16: Target adjusted EBIT margin | B16: 0.2
A17: Margin convergence year | B17: 5
A18: Sales to capital years 1-5 | B18: 2
A19: Sales to capital years 6-10 | B19: =B18+0 -> 2
A20: WACC years 1-5 | B20: 0.075
A21: Terminal WACC | B21: 0.07
A22: Terminal growth | B22: 0.025
A23: Use explicit terminal ROIC / 1=yes | B23: 1
A24: Explicit terminal ROIC | B24: 0.2
A25: Current R&D / USD m | B25: 8.7
A26: R&D amortization life / years | B26: 3
A27: Capitalize R&D / 1=yes | B27: 1
A28: Starting NOL / USD m | B28: 0
A29: Hold starting tax rate / 1=yes | B29: 0
A30: Override reinvestment timing / 1=yes | B30: 0
A31: Reinvestment growth lead / years | B31: 1
... A41: R&D 4 years prior / USD m | B41: 5.6
A42: R&D amortization / USD m | B42: =0+IF(1<=B26,(B38/B26),0)+IF(2<=B26,(B39/B26),0)+IF(3<=B26,(B40/B26),0)+IF(4<=B26,(B41/B26),0) -> 6.4333333
A43: Unamortized R&D asset / USD m | B43: =B25+IF(1<B26,(B38*((B26-1)/B26)),0)+IF(2<B26,(B39*((B26-2)/B26)),0)+IF(3<B26,(B40*((B26-3)/B26)),0)+IF(4<B26,(B41*((B26-4)/B26)),0) -> 16.1
A44: R&D-adjusted base EBIT / USD m | B44: =B3+IF(B27=1,(B25-B42),0) -> 106.05967
A45: Base invested capital / USD m | B45: =B4+B5-B6+IF(B27=1,B43,0) -> 313.437
A46: Effective terminal tax rate | B46: =IF(B29=1,B11,B12) -> 0.25
A47: Effective terminal ROIC | B47: =IF(B23=1,B24,B21) -> 0.2
A48: Cash after explicit haircut / USD m | B48: =B6-IF(B37=1,(B35*(B12-B36)),0) -> 58.13

Sheet WD40_DCF_base
A1: WD40_DCF_base | B1: Base | C1: Y1 | D1: Y2 | E1: Y3 | F1: Y4 | G1: Y5 | H1: Y6 | I1: Y7 | J1: Y8 | K1: Y9 | L1: Y10 | M1: Terminal
A2: Year | B2: 0 | C2: 1 | D2: 2 | E2: 3 | F2: 4 | G2: 5 | H2: 6 | I2: 7 | J2: 8 | K2: 9 | L2: 10 | M2: 11
A3: Revenue growth | C3: ='WD40_Inputs_base'!B13+0 -> 0.060436204 | D3: ='WD40_Inputs_base'!B14+0 -> 0.061544421 | E3: ='WD40_Inputs_base'!B14+0 -> 0.061544421 | F3: ='WD40_Inputs_base'!B14+0 -> 0.061544421 | G3: ='WD40_Inputs_base'!B14+0 -> 0.061544421 | H3: ='WD40_Inputs_base'!B14+0-((('WD40_Inputs_base'!B14+0-'WD40_Inputs_base'!B22+0)/5)*1) -> 0.054235537 | I3: ='WD40_Inputs_base'!B14+0-((('WD40_Inputs_base'!B14+0-'WD40_Inputs_base'!B22+0)/5)*2) -> 0.046926653 | J3: ='WD40_Inputs_base'!B14+0-((('WD40_Inputs_base'!B14+0-'WD40_Inputs_base'!B22+0)/5)*3) -> 0.039617768 | K3: ='WD40_Inputs_base'!B14+0-((('WD40_Inputs_base'!B14+0-'WD40_Inputs_base'!B22+0)/5)*4) -> 0.032308884 | L3: ='WD40_Inputs_base'!B14+0-((('WD40_Inputs_base'!B14+0-'WD40_Inputs_base'!B22+0)/5)*5) -> 0.025 | M3: ='WD40_Inputs_base'!B22+0 -> 0.025
A4: Revenue / USD m | B4: ='WD40_Inputs_base'!B2+0 -> 619.985 | C4: =B4*(1+C3) -> 657.45454 | D4: =C4*(1+D3) -> 697.9172 | E4: =D4*(1+E3) -> 740.87011 | F4: =E4*(1+F3) -> 786.46653 | G4: =F4*(1+G3) -> 834.86916 | H4: =G4*(1+H3) -> 880.14874 | I4: =H4*(1+I3) -> 921.45117 | J4: =I4*(1+J3) -> 957.95701 | ... M4: =L4*(1+M3) -> 1038.971
A5: Adjusted EBIT margin | B5: =B6/B4 -> 0.17106812 | C5: ='WD40_Inputs_base'!B15+0 -> 0.17106812 | D5: =IF(2>'WD40_Inputs_base'!B17+0,'WD40_Inputs_base'!B16+0,'WD40_Inputs_base'!B16+0-((('WD40_Inputs_base'!B16+0-'WD40_Inputs_base'!B15+0)/'WD40_Inputs_base'!B17+0)*('WD40_Inputs_base'!B17+0-2))) -> 0.18264087 | E5: =IF(3>'WD40_Inputs_base'!B17+0,'WD40_Inputs_base'!B16+0,'WD40_Inputs_base'!B16+0-((('WD40_Inputs_base'!B16+0-'WD40_Inputs_base'!B15+0)/'WD40_Inputs_base'!B17+0)*('WD40_Inputs_base'!B17+0-3))) -> 0.18842725 | F5: =IF(4>'WD40_Inputs_base'!B17+0,'WD40_Inputs_base'!B16+0,'WD40_Inputs_base'!B16+0-((('WD40_Inputs_base'!B16+0-'WD40_Inputs_base'!B15+0)/'WD40_Inputs_base'!B17+0)*('WD40_Inputs_base'!B17+0-4))) -> 0.19421362 | G5: =IF(5>'WD40_Inputs_base'!B17+0,'WD40_Inputs_base'!B16+0,'WD40_Inputs_base'!B16+0-((('WD40_Inputs_base'!B16+0-'WD40_Inputs_base'!B15+0)/'WD40_Inputs_base'!B17+0)*('WD40_Inputs_base'!B17+0-5))) -> 0.2 | H5: =IF(6>'WD40_Inputs_base'!B17+0,'WD40_Inputs_base'!B16+0,'WD40_Inputs_base'!B16+0-((('WD40_Inputs_base'!B16+0-'WD40_Inputs_base'!B15+0)/'WD40_Inputs_base'!B17+0)*('WD40_Inputs_base'!B17+0-6))) -> 0.2 | I5: =IF(7>'WD40_Inputs_base'!B17+0,'WD40_Inputs_base'!B16+0,'WD40_Inputs_base'!B16+0-((('WD40_Inputs_base'!B16+0-'WD40_Inputs_base'!B15+0)/'WD40_Inputs_base'!B17+0)*('WD40_Inputs_base'!B17+0-7))) -> 0.2 | J5: =IF(8>'WD40_Inputs_base'!B17+0,'WD40_Inputs_base'!B16+0,'WD40_Inputs_base'!B16+0-((('WD40_Inputs_base'!B16+0-'WD40_Inputs_base'!B15+0)/'WD40_Inputs_base'!B17+0)*('WD40_Inputs_base'!B17+0-8))) -> 0.2 | K5: =IF(9>'WD40_Inputs_base'!B17+0,'WD40_Inputs_base'!B16+0,'WD40_Inputs_base'!B16+0-((('WD40_Inputs_base'!B16+0-'WD40_Inputs_base'!B15+0)/'WD40_Inputs_base'!B17+0)*('WD40_Inputs_base'!B17+0-9))) -> 0.2 | L5: =IF(10>'WD40_Inputs_base'!B17+0,'WD40_Inputs_base'!B16+0,'WD40_Inputs_base'!B16+0-((('WD40_Inputs_base'!B16+0-'WD40_Inputs_base'!B15+0)/'WD40_Inputs_base'!B17+0)*('WD40_Inputs_base'!B17+0-10))) -> 0.2 | M5: =L5 -> 0.2
A6: Adjusted EBIT / USD m | B6: ='WD40_Inputs_base'!B44+0 -> 106.05967 | C6: =C5*C4 -> 112.46951 | D6: =D5*D4 -> 127.4682 | E6: =E5*E4 -> 139.60011 | F6: =F5*F4 -> 152.74251 | G6: =G5*G4 -> 166.97383 | H6: =H5*H4 -> 176.02975 | I6: =I5*I4 -> 184.29023 | J6: =J5*J4 -> 191.5914 | ... L6: =L5*L4 -> 202.72604 | M6: =L5*M4 -> 207.79419
A7: Tax rate | B7: ='WD40_Inputs_base'!B11+0 -> 0.22200028 | C7: ='WD40_Inputs_base'!B11+0 -> 0.22200028 | D7: ='WD40_Inputs_base'!B11+0 -> 0.22200028 | E7: ='WD40_Inputs_base'!B11+0 -> 0.22200028 | F7: ='WD40_Inputs_base'!B11+0 -> 0.22200028 | G7: ='WD40_Inputs_base'!B11+0 -> 0.22200028 | H7: =G7+(('WD40_Inputs_base'!B46+0-'WD40_Inputs_base'!B11+0)/5) -> 0.22760022 | I7: =H7+(('WD40_Inputs_base'!B46+0-'WD40_Inputs_base'!B11+0)/5) -> 0.23320017 | J7: =I7+(('WD40_Inputs_base'!B46+0-'WD40_Inputs_base'!B11+0)/5) -> 0.23880011 | K7: =J7+(('WD40_Inputs_base'!B46+0-'WD40_Inputs_base'!B11+0)/5) -> 0.24440006 | L7: =K7+(('WD40_Inputs_base'!B46+0-'WD40_Inputs_base'!B11+0)/5) -> 0.25 | M7: ='WD40_Inputs_base'!B46+0 -> 0.25
A8: Opening NOL / USD m | C8: =B12 -> 0 | D8: =C12 -> 0 | E8: =D12 -> 0 | F8: =E12 -> 0 | G8: =F12 -> 0 | H8: =G12 -> 0 | I8: =H12 -> 0 | J8: =I12 -> 0 | ... M8: =L12 -> 0
A9: NOPAT / USD m | B9: =IF(B6>0,(B6*(1-B7)),B6) -> 82.514391 | C9: =IF(C6>0,IF(C6<B12,C6,C6-((C6-B12)*C7)),C6) -> 87.501248 | D9: =IF(D6>0,IF(D6<C12,D6,D6-((D6-C12)*D7)),D6) -> 99.170228 | E9: =IF(E6>0,IF(E6<D12,E6,E6-((E6-D12)*E7)),E6) -> 108.60885 | F9: =IF(F6>0,IF(F6<E12,F6,F6-((F6-E12)*F7)),F6) -> 118.83363 | G9: =IF(G6>0,IF(G6<F12,G6,G6-((G6-F12)*G7)),G6) -> 129.9056 | H9: =IF(H6>0,IF(H6<G12,H6,H6-((H6-G12)*H7)),H6) -> 135.96534 | I9: =IF(I6>0,IF(I6<H12,I6,I6-((I6-H12)*I7)),I6) -> 141.31372 | J9: =IF(J6>0,IF(J6<I12,J6,J6-((J6-I12)*J7)),J6) -> 145.83935 | ... L9: =IF(L6>0,IF(L6<K12,L6,L6-((L6-K12)*L7)),L6) -> 152.04453 | M9: =M6*(1-M7) -> 155.84565
