Workbook

Sheet Scenario inputs
B1: Original | C1: Bear | D1: Base | E1: Bull
A2: Revenue FY2025 (USD m) | B2: 619.985 | C2: 619.985 | D2: 619.985 | E2: 619.985
A3: EBIT FY2025 after R&D capitalization (USD m) | B3: 106.05967 | C3: 106.05967 | D3: 106.05967 | E3: 106.05967
A4: Invested capital FY2025 (USD m) | B4: 313.437 | C4: 313.437 | D4: 313.437 | E4: 313.437
A5: Debt (USD m) | B5: 86.995 | C5: 86.995 | D5: 86.995 | E5: 86.995
A6: Cash (USD m) | B6: 58.13 | C6: 58.13 | D6: 58.13 | E6: 58.13
A7: Minority interests (USD m) | B7: 0 | C7: 0 | D7: 0 | E7: 0
A8: Non-operating assets (USD m) | B8: 0 | C8: 0 | D8: 0 | E8: 0
A9: Value of employee options (USD m) | B9: 0 | C9: 0 | D9: 0 | E9: 0
A10: Shares, DCF denominator (million) | B10: 13.633263 | C10: 13.633263 | D10: 13.633263 | E10: 13.633263
A11: Revenue growth, year 1 (rate) | B11: 0.05 | C11: 0.016154 | D11: 0.036315 | E11: 0.056477
A12: Revenue growth, years 2-5 (rate) | B12: 0.05 | C12: 0.04 | D12: 0.06 | E12: 0.07
A13: Revenue growth after year 10 (rate) | B13: 0.025 | C13: 0.02 | D13: 0.025 | E13: 0.03
... A24: Terminal ROIC when the override is on (rate) | B24: 0.15 | C24: 0.15 | D24: 0.15 | E24: 0.2

Sheet DCF Original
B1: Base year | C1: Year 1 | D1: Year 2 | E1: Year 3 | F1: Year 4 | G1: Year 5 | H1: Year 6 | I1: Year 7 | J1: Year 8 | K1: Year 9 | L1: Year 10 | M1: Terminal year
A2: Year | B2: 0 | C2: 1 | D2: 2 | E2: 3 | F2: 4 | G2: 5 | H2: 6 | I2: 7 | J2: 8 | K2: 9 | L2: 10
A3: Revenue growth | C3: ='Scenario inputs'!B11 -> 0.05 | D3: ='Scenario inputs'!B12 -> 0.05 | E3: ='Scenario inputs'!B12 -> 0.05 | F3: ='Scenario inputs'!B12 -> 0.05 | G3: ='Scenario inputs'!B12 -> 0.05 | H3: =G3-((G3-M3)/5)*1 -> 0.045 | I3: =G3-((G3-M3)/5)*2 -> 0.04 | J3: =G3-((G3-M3)/5)*3 -> 0.035 | K3: =G3-((G3-M3)/5)*4 -> 0.03 | L3: =G3-((G3-M3)/5)*5 -> 0.025 | M3: ='Scenario inputs'!B13 -> 0.025
A4: Revenue | B4: ='Scenario inputs'!B2 -> 619.985 | C4: =B4*(1+C3) -> 650.98425 | D4: =C4*(1+D3) -> 683.53346 | E4: =D4*(1+E3) -> 717.71014 | F4: =E4*(1+F3) -> 753.59564 | G4: =F4*(1+G3) -> 791.27542 | H4: =G4*(1+H3) -> 826.88282 | I4: =H4*(1+I3) -> 859.95813 | J4: =I4*(1+J3) -> 890.05667 | ... M4: =L4*(1+M3) -> 963.16926
A5: Operating margin | B5: =B6/B4 -> 0.17106812 | C5: ='Scenario inputs'!B14 -> 0.17106812 | D5: =IF(D2>'Scenario inputs'!B16,'Scenario inputs'!B15,'Scenario inputs'!B15-(('Scenario inputs'!B15-C5)/'Scenario inputs'!B16)*('Scenario inputs'!B16-D2)) -> 0.17106812 | E5: =IF(E2>'Scenario inputs'!B16,'Scenario inputs'!B15,'Scenario inputs'!B15-(('Scenario inputs'!B15-C5)/'Scenario inputs'!B16)*('Scenario inputs'!B16-E2)) -> 0.17106812 | F5: =IF(F2>'Scenario inputs'!B16,'Scenario inputs'!B15,'Scenario inputs'!B15-(('Scenario inputs'!B15-C5)/'Scenario inputs'!B16)*('Scenario inputs'!B16-F2)) -> 0.17106812 | G5: =IF(G2>'Scenario inputs'!B16,'Scenario inputs'!B15,'Scenario inputs'!B15-(('Scenario inputs'!B15-C5)/'Scenario inputs'!B16)*('Scenario inputs'!B16-G2)) -> 0.17106812 | H5: =IF(H2>'Scenario inputs'!B16,'Scenario inputs'!B15,'Scenario inputs'!B15-(('Scenario inputs'!B15-C5)/'Scenario inputs'!B16)*('Scenario inputs'!B16-H2)) -> 0.17106812 | I5: =IF(I2>'Scenario inputs'!B16,'Scenario inputs'!B15,'Scenario inputs'!B15-(('Scenario inputs'!B15-C5)/'Scenario inputs'!B16)*('Scenario inputs'!B16-I2)) -> 0.17106812 | J5: =IF(J2>'Scenario inputs'!B16,'Scenario inputs'!B15,'Scenario inputs'!B15-(('Scenario inputs'!B15-C5)/'Scenario inputs'!B16)*('Scenario inputs'!B16-J2)) -> 0.17106812 | K5: =IF(K2>'Scenario inputs'!B16,'Scenario inputs'!B15,'Scenario inputs'!B15-(('Scenario inputs'!B15-C5)/'Scenario inputs'!B16)*('Scenario inputs'!B16-K2)) -> 0.17106812 | L5: =IF(L2>'Scenario inputs'!B16,'Scenario inputs'!B15,'Scenario inputs'!B15-(('Scenario inputs'!B15-C5)/'Scenario inputs'!B16)*('Scenario inputs'!B16-L2)) -> 0.17106812 | M5: =(L5) -> 0.17106812
A6: EBIT | B6: ='Scenario inputs'!B3 -> 106.05967 | C6: =C5*C4 -> 111.36265 | D6: =D5*D4 -> 116.93078 | E6: =E5*E4 -> 122.77732 | F6: =F5*F4 -> 128.91619 | G6: =G5*G4 -> 135.362 | H6: =H5*H4 -> 141.45329 | I6: =I5*I4 -> 147.11142 | J6: =J5*J4 -> 152.26032 | ... M6: =M5*M4 -> 164.76755
A7: Tax rate | B7: ='Scenario inputs'!B17 -> 0.22200028 | C7: =(B7) -> 0.22200028 | D7: =(C7) -> 0.22200028 | E7: =(D7) -> 0.22200028 | F7: =(E7) -> 0.22200028 | G7: =(F7) -> 0.22200028 | H7: =G7+(M7-G7)/5 -> 0.22760022 | I7: =H7+(M7-G7)/5 -> 0.23320017 | J7: =I7+(M7-G7)/5 -> 0.23880011 | K7: =J7+(M7-G7)/5 -> 0.24440006 | L7: =K7+(M7-G7)/5 -> 0.25 | M7: ='Scenario inputs'!B18 -> 0.25
A8: NOPAT | B8: =IF(B6>0,B6*(1-B7),B6) -> 82.514391 | C8: =IF(C6>0,C6*(1-C7),C6) -> 86.640111 | D8: =IF(D6>0,D6*(1-D7),D6) -> 90.972117 | E8: =IF(E6>0,E6*(1-E7),E6) -> 95.520722 | F8: =IF(F6>0,F6*(1-F7),F6) -> 100.29676 | G8: =IF(G6>0,G6*(1-G7),G6) -> 105.3116 | H8: =IF(H6>0,H6*(1-H7),H6) -> 109.25849 | I8: =IF(I6>0,I6*(1-I7),I6) -> 112.80501 | ... L8: =IF(L6>0,L6*(1-L7),L6) -> 120.56162 | M8: =M6*(1-M7) -> 123.57566
A9: Sales to capital | C9: ='Scenario inputs'!B19 -> 2 | D9: ='Scenario inputs'!B19 -> 2 | E9: ='Scenario inputs'!B19 -> 2 | F9: ='Scenario inputs'!B19 -> 2 | G9: ='Scenario inputs'!B19 -> 2 | H9: ='Scenario inputs'!B20 -> 2 | I9: ='Scenario inputs'!B20 -> 2 | J9: ='Scenario inputs'!B20 -> 2 | K9: ='Scenario inputs'!B20 -> 2 | L9: ='Scenario inputs'!B20 -> 2
A10: Reinvestment | C10: =(D4-C4)/C9 -> 16.274606 | D10: =(E4-D4)/D9 -> 17.088337 | E10: =(F4-E4)/E9 -> 17.942753 | F10: =(G4-F4)/F9 -> 18.839891 | G10: =(H4-G4)/G9 -> 17.803697 | H10: =(I4-H4)/H9 -> 16.537656 | I10: =(J4-I4)/I9 -> 15.049267 | J10: =(K4-J4)/J9 -> 13.35085 | ... L10: =(M4-L4)/L9 -> 11.745967 | M10: =IF(M3>0,(M3/B17)*M8,0) -> 38.617395
A11: FCFF | C11: =C8-C10 -> 70.365505 | D11: =D8-D10 -> 73.88378 | E11: =E8-E10 -> 77.577969 | F11: =F8-F10 -> 81.456867 | G11: =G8-G10 -> 87.507899 | H11: =H8-H10 -> 92.720831 | I11: =I8-I10 -> 97.755744 | J11: =J8-J10 -> 102.54969 | ... M11: =M8-M10 -> 84.958269
A12: WACC | C12: ='Scenario inputs'!B21 -> 0.09 | D12: ='Scenario inputs'!B21 -> 0.09 | E12: ='Scenario inputs'!B21 -> 0.09 | F12: ='Scenario inputs'!B21 -> 0.09 | G12: ='Scenario inputs'!B21 -> 0.09 | H12: =G12-(G12-M12)/5 -> 0.088 | I12: =H12-(G12-M12)/5 -> 0.086 | J12: =I12-(G12-M12)/5 -> 0.084 | K12: =J12-(G12-M12)/5 -> 0.082 | L12: =K12-(G12-M12)/5 -> 0.08 | M12: ='Scenario inputs'!B22 -> 0.08
A13: Cumulative discount factor | C13: =1/(1+C12) -> 0.91743119 | D13: =C13*(1/(1+D12)) -> 0.84167999 | E13: =D13*(1/(1+E12)) -> 0.77218348 | F13: =E13*(1/(1+F12)) -> 0.70842521 | G13: =F13*(1/(1+G12)) -> 0.64993139 | H13: =G13*(1/(1+H12)) -> 0.59736341 | I13: =H13*(1/(1+I12)) -> 0.55005839 | J13: =I13*(1/(1+J12)) -> 0.50743393 | K13: =J13*(1/(1+K12)) -> 0.46897776 | L13: =K13*(1/(1+L12)) -> 0.43423867
A14: PV of FCFF | C14: =C11*C13 -> 64.555509 | D14: =D11*D13 -> 62.186499 | E14: =E11*E13 -> 59.904426 | F14: =F11*F13 -> 57.706099 | G14: =G11*G13 -> 56.87413 | H14: =H11*H13 -> 55.388032 | I14: =I11*I13 -> 53.771367 | J14: =J11*J13 -> 52.037191 | ... L14: =L11*L13 -> 47.251965
A15: Invested capital | B15: ='Scenario inputs'!B4 -> 313.437 | C15: =B15+C10 -> 329.71161 | D15: =C15+D10 -> 346.79994 | E15: =D15+E10 -> 364.7427 | F15: =E15+F10 -> 383.58259 | G15: =F15+G10 -> 401.38628 | H15: =G15+H10 -> 417.92394 | I15: =H15+I10 -> 432.97321 | J15: =I15+J10 -> 446.32406 | ... L15: =K15+L10 -> 469.5295
A16: ROIC | B16: =B8/B15 -> 0.2632567 | C16: =C8/B15 -> 0.27641954 | D16: =D8/C15 -> 0.27591421 | E16: =E8/D15 -> 0.27543465 | F16: =F8/E15 -> 0.27497948 | G16: =G8/F15 -> 0.27454739 | H16: =H8/G15 -> 0.27220284 | I16: =I8/H15 -> 0.26991756 | J16: =J8/I15 -> 0.26768524 | ... L16: =L8/K15 -> 0.26335946
A17: Terminal ROIC | B17: =IF('Scenario inputs'!B23=1,'Scenario inputs'!B24,L12) -> 0.08
A18: Terminal value | B18: =M11/(M12-M3) -> 1544.6958
A19: PV of terminal value | B19: =B18*L13 -> 670.76664
A20: Sum of PV of FCFF, years 1-10 | B20: =SUM(C14:L14) -> 559.87453
A21: Operating assets | B21: =B19+B20 -> 1230.6412
A22: Debt | B22: ='Scenario inputs'!B5 -> 86.995
A23: Cash | B23: ='Scenario inputs'!B6 -> 58.13
A24: Minority interests | B24: ='Scenario inputs'!B7 -> 0
A25: Non-operating assets | B25: ='Scenario inputs'!B8 -> 0
A26: Equity value | B26: =B21-B22-B24+B23+B25 -> 1201.7762
A27: Value of employee options | B27: ='Scenario inputs'!B9 -> 0
A28: Common equity | B28: =B26-B27 -> 1201.7762
A29: Shares | B29: ='Scenario inputs'!B10 -> 13.633263
A30: Value per share | B30: =B28/B29 -> 88.150296
A31: PV of terminal value / operating assets | B31: =B19/B21 -> 0.54505461

Sheet DCF Bear
B1: Base year | C1: Year 1 | D1: Year 2 | E1: Year 3 | F1: Year 4 | G1: Year 5 | H1: Year 6 | I1: Year 7 | J1: Year 8 | K1: Year 9 | L1: Year 10 | M1: Terminal year
A2: Year | B2: 0 | C2: 1 | D2: 2 | E2: 3 | F2: 4 | G2: 5 | H2: 6 | I2: 7 | J2: 8 | K2: 9 | L2: 10
A3: Revenue growth | C3: ='Scenario inputs'!C11 -> 0.016154 | D3: ='Scenario inputs'!C12 -> 0.04 | E3: ='Scenario inputs'!C12 -> 0.04 | F3: ='Scenario inputs'!C12 -> 0.04 | G3: ='Scenario inputs'!C12 -> 0.04 | H3: =G3-((G3-M3)/5)*1 -> 0.036 | I3: =G3-((G3-M3)/5)*2 -> 0.032 | J3: =G3-((G3-M3)/5)*3 -> 0.028 | K3: =G3-((G3-M3)/5)*4 -> 0.024 | L3: =G3-((G3-M3)/5)*5 -> 0.02 | M3: ='Scenario inputs'!C13 -> 0.02
A4: Revenue | B4: ='Scenario inputs'!C2 -> 619.985 | C4: =B4*(1+C3) -> 630.00024 | D4: =C4*(1+D3) -> 655.20025 | E4: =D4*(1+E3) -> 681.40826 | F4: =E4*(1+F3) -> 708.66459 | G4: =F4*(1+G3) -> 737.01117 | H4: =G4*(1+H3) -> 763.54357 | I4: =H4*(1+I3) -> 787.97697 | J4: =I4*(1+J3) -> 810.04032 | ... M4: =L4*(1+M3) -> 862.99233
A5: Operating margin | B5: =B6/B4 -> 0.17106812 | C5: ='Scenario inputs'!C14 -> 0.163839 | D5: =IF(D2>'Scenario inputs'!C16,'Scenario inputs'!C15,'Scenario inputs'!C15-(('Scenario inputs'!C15-C5)/'Scenario inputs'!C16)*('Scenario inputs'!C16-D2)) -> 0.163839 | E5: =IF(E2>'Scenario inputs'!C16,'Scenario inputs'!C15,'Scenario inputs'!C15-(('Scenario inputs'!C15-C5)/'Scenario inputs'!C16)*('Scenario inputs'!C16-E2)) -> 0.163839 | F5: =IF(F2>'Scenario inputs'!C16,'Scenario inputs'!C15,'Scenario inputs'!C15-(('Scenario inputs'!C15-C5)/'Scenario inputs'!C16)*('Scenario inputs'!C16-F2)) -> 0.163839 | G5: =IF(G2>'Scenario inputs'!C16,'Scenario inputs'!C15,'Scenario inputs'!C15-(('Scenario inputs'!C15-C5)/'Scenario inputs'!C16)*('Scenario inputs'!C16-G2)) -> 0.163839 | H5: =IF(H2>'Scenario inputs'!C16,'Scenario inputs'!C15,'Scenario inputs'!C15-(('Scenario inputs'!C15-C5)/'Scenario inputs'!C16)*('Scenario inputs'!C16-H2)) -> 0.163839 | I5: =IF(I2>'Scenario inputs'!C16,'Scenario inputs'!C15,'Scenario inputs'!C15-(('Scenario inputs'!C15-C5)/'Scenario inputs'!C16)*('Scenario inputs'!C16-I2)) -> 0.163839 | J5: =IF(J2>'Scenario inputs'!C16,'Scenario inputs'!C15,'Scenario inputs'!C15-(('Scenario inputs'!C15-C5)/'Scenario inputs'!C16)*('Scenario inputs'!C16-J2)) -> 0.163839 | K5: =IF(K2>'Scenario inputs'!C16,'Scenario inputs'!C15,'Scenario inputs'!C15-(('Scenario inputs'!C15-C5)/'Scenario inputs'!C16)*('Scenario inputs'!C16-K2)) -> 0.163839 | L5: =IF(L2>'Scenario inputs'!C16,'Scenario inputs'!C15,'Scenario inputs'!C15-(('Scenario inputs'!C15-C5)/'Scenario inputs'!C16)*('Scenario inputs'!C16-L2)) -> 0.163839 | M5: =(L5) -> 0.163839
A6: EBIT | B6: ='Scenario inputs'!C3 -> 106.05967 | C6: =C5*C4 -> 103.21861 | D6: =D5*D4 -> 107.34735 | E6: =E5*E4 -> 111.64125 | F6: =F5*F4 -> 116.1069 | G6: =G5*G4 -> 120.75117 | H6: =H5*H4 -> 125.09822 | I6: =I5*I4 -> 129.10136 | J6: =J5*J4 -> 132.7162 | ... M6: =M5*M4 -> 141.3918
A7: Tax rate | B7: ='Scenario inputs'!C17 -> 0.235 | C7: =(B7) -> 0.235 | D7: =(C7) -> 0.235 | E7: =(D7) -> 0.235 | F7: =(E7) -> 0.235 | G7: =(F7) -> 0.235 | H7: =G7+(M7-G7)/5 -> 0.238 | I7: =H7+(M7-G7)/5 -> 0.241 | J7: =I7+(M7-G7)/5 -> 0.244 | K7: =J7+(M7-G7)/5 -> 0.247 | L7: =K7+(M7-G7)/5 -> 0.25 | M7: ='Scenario inputs'!C18 -> 0.25
A8: NOPAT | B8: =IF(B6>0,B6*(1-B7),B6) -> 81.135645 | C8: =IF(C6>0,C6*(1-C7),C6) -> 78.962236 | D8: =IF(D6>0,D6*(1-D7),D6) -> 82.120725 | E8: =IF(E6>0,E6*(1-E7),E6) -> 85.405554 | F8: =IF(F6>0,F6*(1-F7),F6) -> 88.821776 | G8: =IF(G6>0,G6*(1-G7),G6) -> 92.374648 | H8: =IF(H6>0,H6*(1-H7),H6) -> 95.32484 | I8: =IF(I6>0,I6*(1-I7),I6) -> 97.987931 | ... L8: =IF(L6>0,L6*(1-L7),L6) -> 103.96456 | M8: =M6*(1-M7) -> 106.04385
A9: Sales to capital | C9: ='Scenario inputs'!C19 -> 2 | D9: ='Scenario inputs'!C19 -> 2 | E9: ='Scenario inputs'!C19 -> 2 | F9: ='Scenario inputs'!C19 -> 2 | G9: ='Scenario inputs'!C19 -> 2 | H9: ='Scenario inputs'!C20 -> 2 | I9: ='Scenario inputs'!C20 -> 2 | J9: ='Scenario inputs'!C20 -> 2 | K9: ='Scenario inputs'!C20 -> 2 | L9: ='Scenario inputs'!C20 -> 2
A10: Reinvestment | C10: =(D4-C4)/C9 -> 12.600005 | D10: =(E4-D4)/D9 -> 13.104005 | E10: =(F4-E4)/E9 -> 13.628165 | F10: =(G4-F4)/F9 -> 14.173292 | G10: =(H4-G4)/G9 -> 13.266201 | H10: =(I4-H4)/H9 -> 12.216697 | I10: =(J4-I4)/I9 -> 11.031678 | J10: =(K4-J4)/J9 -> 9.7204839 | ... L10: =(M4-L4)/L9 -> 8.4607092 | M10: =IF(M3>0,(M3/B17)*M8,0) -> 25.487328
A11: FCFF | C11: =C8-C10 -> 66.362231 | D11: =D8-D10 -> 69.01672 | E11: =E8-E10 -> 71.777389 | F11: =F8-F10 -> 74.648485 | G11: =G8-G10 -> 79.108446 | H11: =H8-H10 -> 83.108143 | I11: =I8-I10 -> 86.956253 | J11: =J8-J10 -> 90.612961 | ... M11: =M8-M10 -> 80.556523
A12: WACC | C12: ='Scenario inputs'!C21 -> 0.077021 | D12: ='Scenario inputs'!C21 -> 0.077021 | E12: ='Scenario inputs'!C21 -> 0.077021 | F12: ='Scenario inputs'!C21 -> 0.077021 | G12: ='Scenario inputs'!C21 -> 0.077021 | H12: =G12-(G12-M12)/5 -> 0.0782594 | I12: =H12-(G12-M12)/5 -> 0.0794978 | J12: =I12-(G12-M12)/5 -> 0.0807362 | K12: =J12-(G12-M12)/5 -> 0.0819746 | L12: =K12-(G12-M12)/5 -> 0.083213 | M12: ='Scenario inputs'!C22 -> 0.083213
A13: Cumulative discount factor | C13: =1/(1+C12) -> 0.928487 | D13: =C13*(1/(1+D12)) -> 0.86208811 | E13: =D13*(1/(1+E12)) -> 0.80043761 | F13: =E13*(1/(1+F12)) -> 0.74319592 | G13: =F13*(1/(1+G12)) -> 0.69004775 | H13: =G13*(1/(1+H12)) -> 0.63996451 | I13: =H13*(1/(1+I12)) -> 0.5928354 | J13: =I13*(1/(1+J12)) -> 0.54854774 | K13: =J13*(1/(1+K12)) -> 0.50698763 | L13: =K13*(1/(1+L12)) -> 0.46804057
A14: PV of FCFF | C14: =C11*C13 -> 61.616469 | D14: =D11*D13 -> 59.498494 | E14: =E11*E13 -> 57.453322 | F14: =F11*F13 -> 55.478449 | G14: =G11*G13 -> 54.588605 | H14: =H11*H13 -> 53.186262 | I14: =I11*I13 -> 51.550745 | J14: =J11*J13 -> 49.705535 | ... L14: =L11*L13 -> 44.699677
A15: Invested capital | B15: ='Scenario inputs'!C4 -> 313.437 | C15: =B15+C10 -> 326.037 | D15: =C15+D10 -> 339.14101 | E15: =D15+E10 -> 352.76917 | F15: =E15+F10 -> 366.94247 | G15: =F15+G10 -> 380.20867 | H15: =G15+H10 -> 392.42536 | I15: =H15+I10 -> 403.45704 | J15: =I15+J10 -> 413.17753 | ... L15: =K15+L10 -> 429.93305
A16: ROIC | B16: =B8/B15 -> 0.2588579 | C16: =C8/B15 -> 0.25192379 | D16: =D8/C15 -> 0.25187547 | E16: =E8/D15 -> 0.25182904 | F16: =F8/E15 -> 0.2517844 | G16: =G8/F15 -> 0.2517415 | H16: =H8/G15 -> 0.25071717 | I16: =I8/H15 -> 0.24969826 | J16: =J8/I15 -> 0.24868433 | ... L16: =L8/K15 -> 0.24666995
A17: Terminal ROIC | B17: =IF('Scenario inputs'!C23=1,'Scenario inputs'!C24,L12) -> 0.083213
A18: Terminal value | B18: =M11/(M12-M3) -> 1274.3664
A19: PV of terminal value | B19: =B18*L13 -> 596.45518
A20: Sum of PV of FCFF, years 1-10 | B20: =SUM(C14:L14) -> 535.45413
A21: Operating assets | B21: =B19+B20 -> 1131.9093
A22: Debt | B22: ='Scenario inputs'!C5 -> 86.995
A23: Cash | B23: ='Scenario inputs'!C6 -> 58.13
A24: Minority interests | B24: ='Scenario inputs'!C7 -> 0
A25: Non-operating assets | B25: ='Scenario inputs'!C8 -> 0
A26: Equity value | B26: =B21-B22-B24+B23+B25 -> 1103.0443
A27: Value of employee options | B27: ='Scenario inputs'!C9 -> 0
A28: Common equity | B28: =B26-B27 -> 1103.0443
A29: Shares | B29: ='Scenario inputs'!C10 -> 13.633263
A30: Value per share | B30: =B28/B29 -> 80.908313
A31: PV of terminal value / operating assets | B31: =B19/B21 -> 0.52694608

Sheet DCF Base
B1: Base year | C1: Year 1 | D1: Year 2 | E1: Year 3 | F1: Year 4 | G1: Year 5 | H1: Year 6 | I1: Year 7 | J1: Year 8 | K1: Year 9 | L1: Year 10 | M1: Terminal year
A2: Year | B2: 0 | C2: 1 | D2: 2 | E2: 3 | F2: 4 | G2: 5 | H2: 6 | I2: 7 | J2: 8 | K2: 9 | L2: 10
A3: Revenue growth | C3: ='Scenario inputs'!D11 -> 0.036315 | D3: ='Scenario inputs'!D12 -> 0.06 | E3: ='Scenario inputs'!D12 -> 0.06 | F3: ='Scenario inputs'!D12 -> 0.06 | G3: ='Scenario inputs'!D12 -> 0.06 | H3: =G3-((G3-M3)/5)*1 -> 0.053 | I3: =G3-((G3-M3)/5)*2 -> 0.046 | J3: =G3-((G3-M3)/5)*3 -> 0.039 | K3: =G3-((G3-M3)/5)*4 -> 0.032 | L3: =G3-((G3-M3)/5)*5 -> 0.025 | M3: ='Scenario inputs'!D13 -> 0.025
A4: Revenue | B4: ='Scenario inputs'!D2 -> 619.985 | C4: =B4*(1+C3) -> 642.49976 | D4: =C4*(1+D3) -> 681.04974 | E4: =D4*(1+E3) -> 721.91273 | F4: =E4*(1+F3) -> 765.22749 | G4: =F4*(1+G3) -> 811.14114 | H4: =G4*(1+H3) -> 854.13162 | I4: =H4*(1+I3) -> 893.42167 | J4: =I4*(1+J3) -> 928.26512 | ... M4: =L4*(1+M3) -> 1006.4668
A5: Operating margin | B5: =B6/B4 -> 0.17106812 | C5: ='Scenario inputs'!D14 -> 0.169287 | D5: =IF(D2>'Scenario inputs'!D16,'Scenario inputs'!D15,'Scenario inputs'!D15-(('Scenario inputs'!D15-C5)/'Scenario inputs'!D16)*('Scenario inputs'!D16-D2)) -> 0.1735722 | E5: =IF(E2>'Scenario inputs'!D16,'Scenario inputs'!D15,'Scenario inputs'!D15-(('Scenario inputs'!D15-C5)/'Scenario inputs'!D16)*('Scenario inputs'!D16-E2)) -> 0.1757148 | F5: =IF(F2>'Scenario inputs'!D16,'Scenario inputs'!D15,'Scenario inputs'!D15-(('Scenario inputs'!D15-C5)/'Scenario inputs'!D16)*('Scenario inputs'!D16-F2)) -> 0.1778574 | G5: =IF(G2>'Scenario inputs'!D16,'Scenario inputs'!D15,'Scenario inputs'!D15-(('Scenario inputs'!D15-C5)/'Scenario inputs'!D16)*('Scenario inputs'!D16-G2)) -> 0.18 | H5: =IF(H2>'Scenario inputs'!D16,'Scenario inputs'!D15,'Scenario inputs'!D15-(('Scenario inputs'!D15-C5)/'Scenario inputs'!D16)*('Scenario inputs'!D16-H2)) -> 0.18 | I5: =IF(I2>'Scenario inputs'!D16,'Scenario inputs'!D15,'Scenario inputs'!D15-(('Scenario inputs'!D15-C5)/'Scenario inputs'!D16)*('Scenario inputs'!D16-I2)) -> 0.18 | J5: =IF(J2>'Scenario inputs'!D16,'Scenario inputs'!D15,'Scenario inputs'!D15-(('Scenario inputs'!D15-C5)/'Scenario inputs'!D16)*('Scenario inputs'!D16-J2)) -> 0.18 | K5: =IF(K2>'Scenario inputs'!D16,'Scenario inputs'!D15,'Scenario inputs'!D15-(('Scenario inputs'!D15-C5)/'Scenario inputs'!D16)*('Scenario inputs'!D16-K2)) -> 0.18 | L5: =IF(L2>'Scenario inputs'!D16,'Scenario inputs'!D15,'Scenario inputs'!D15-(('Scenario inputs'!D15-C5)/'Scenario inputs'!D16)*('Scenario inputs'!D16-L2)) -> 0.18 | M5: =(L5) -> 0.18
A6: EBIT | B6: ='Scenario inputs'!D3 -> 106.05967 | C6: =C5*C4 -> 108.76686 | D6: =D5*D4 -> 118.2113 | E6: =E5*E4 -> 126.85075 | F6: =F5*F4 -> 136.10137 | G6: =G5*G4 -> 146.0054 | H6: =H5*H4 -> 153.74369 | I6: =I5*I4 -> 160.8159 | J6: =J5*J4 -> 167.08772 | ... M6: =M5*M4 -> 181.16403
A7: Tax rate | B7: ='Scenario inputs'!D17 -> 0.23 | C7: =(B7) -> 0.23 | D7: =(C7) -> 0.23 | E7: =(D7) -> 0.23 | F7: =(E7) -> 0.23 | G7: =(F7) -> 0.23 | H7: =G7+(M7-G7)/5 -> 0.234 | I7: =H7+(M7-G7)/5 -> 0.238 | J7: =I7+(M7-G7)/5 -> 0.242 | K7: =J7+(M7-G7)/5 -> 0.246 | L7: =K7+(M7-G7)/5 -> 0.25 | M7: ='Scenario inputs'!D18 -> 0.25
A8: NOPAT | B8: =IF(B6>0,B6*(1-B7),B6) -> 81.665943 | C8: =IF(C6>0,C6*(1-C7),C6) -> 83.750479 | D8: =IF(D6>0,D6*(1-D7),D6) -> 91.022702 | E8: =IF(E6>0,E6*(1-E7),E6) -> 97.675078 | F8: =IF(F6>0,F6*(1-F7),F6) -> 104.79806 | G8: =IF(G6>0,G6*(1-G7),G6) -> 112.42416 | H8: =IF(H6>0,H6*(1-H7),H6) -> 117.76767 | I8: =IF(I6>0,I6*(1-I7),I6) -> 122.54172 | ... L8: =IF(L6>0,L6*(1-L7),L6) -> 132.55904 | M8: =M6*(1-M7) -> 135.87302
A9: Sales to capital | C9: ='Scenario inputs'!D19 -> 2 | D9: ='Scenario inputs'!D19 -> 2 | E9: ='Scenario inputs'!D19 -> 2 | F9: ='Scenario inputs'!D19 -> 2 | G9: ='Scenario inputs'!D19 -> 2 | H9: ='Scenario inputs'!D20 -> 2 | I9: ='Scenario inputs'!D20 -> 2 | J9: ='Scenario inputs'!D20 -> 2 | K9: ='Scenario inputs'!D20 -> 2 | L9: ='Scenario inputs'!D20 -> 2
A10: Reinvestment | C10: =(D4-C4)/C9 -> 19.274993 | D10: =(E4-D4)/D9 -> 20.431492 | E10: =(F4-E4)/E9 -> 21.657382 | F10: =(G4-F4)/F9 -> 22.956825 | G10: =(H4-G4)/G9 -> 21.49524 | H10: =(I4-H4)/H9 -> 19.645027 | I10: =(J4-I4)/I9 -> 17.421723 | J10: =(K4-J4)/J9 -> 14.852242 | ... L10: =(M4-L4)/L9 -> 12.273986 | M10: =IF(M3>0,(M3/B17)*M8,0) -> 22.645503
A11: FCFF | C11: =C8-C10 -> 64.475487 | D11: =D8-D10 -> 70.59121 | E11: =E8-E10 -> 76.017696 | F11: =F8-F10 -> 81.841231 | G11: =G8-G10 -> 90.928922 | H11: =H8-H10 -> 98.12264 | I11: =I8-I10 -> 105.11999 | J11: =J8-J10 -> 111.80025 | ... M11: =M8-M10 -> 113.22752
A12: WACC | C12: ='Scenario inputs'!D21 -> 0.074014 | D12: ='Scenario inputs'!D21 -> 0.074014 | E12: ='Scenario inputs'!D21 -> 0.074014 | F12: ='Scenario inputs'!D21 -> 0.074014 | G12: ='Scenario inputs'!D21 -> 0.074014 | H12: =G12-(G12-M12)/5 -> 0.074014 | I12: =H12-(G12-M12)/5 -> 0.074014 | J12: =I12-(G12-M12)/5 -> 0.074014 | K12: =J12-(G12-M12)/5 -> 0.074014 | L12: =K12-(G12-M12)/5 -> 0.074014 | M12: ='Scenario inputs'!D22 -> 0.074014
A13: Cumulative discount factor | C13: =1/(1+C12) -> 0.93108656 | D13: =C13*(1/(1+D12)) -> 0.86692218 | E13: =D13*(1/(1+E12)) -> 0.80717959 | F13: =E13*(1/(1+F12)) -> 0.75155407 | G13: =F13*(1/(1+G12)) -> 0.69976189 | H13: =G13*(1/(1+H12)) -> 0.65153889 | I13: =H13*(1/(1+I12)) -> 0.60663911 | J13: =I13*(1/(1+J12)) -> 0.56483352 | K13: =J13*(1/(1+K12)) -> 0.5259089 | L13: =K13*(1/(1+L12)) -> 0.4896667
A14: PV of FCFF | C14: =C11*C13 -> 60.032259 | D14: =D11*D13 -> 61.197086 | E14: =E11*E13 -> 61.359933 | F14: =F11*F13 -> 61.50811 | G14: =G11*G13 -> 63.628594 | H14: =H11*H13 -> 63.930716 | I14: =I11*I13 -> 63.769899 | J14: =J11*J13 -> 63.148529 | ... L14: =L11*L13 -> 58.899588
A15: Invested capital | B15: ='Scenario inputs'!D4 -> 313.437 | C15: =B15+C10 -> 332.71199 | D15: =C15+D10 -> 353.14348 | E15: =D15+E10 -> 374.80087 | F15: =E15+F10 -> 397.75769 | G15: =F15+G10 -> 419.25293 | H15: =G15+H10 -> 438.89796 | I15: =H15+I10 -> 456.31968 | J15: =I15+J10 -> 471.17192 | ... L15: =K15+L10 -> 495.42053
A16: ROIC | B16: =B8/B15 -> 0.26054979 | C16: =C8/B15 -> 0.26720036 | D16: =D8/C15 -> 0.27357806 | E16: =E8/D15 -> 0.27658751 | F16: =F8/E15 -> 0.27960996 | G16: =G8/F15 -> 0.28264485 | H16: =H8/G15 -> 0.28089885 | I16: =I8/H15 -> 0.2792032 | J16: =J8/I15 -> 0.27755212 | ... L16: =L8/K15 -> 0.27436612
A17: Terminal ROIC | B17: =IF('Scenario inputs'!D23=1,'Scenario inputs'!D24,L12) -> 0.15
A18: Terminal value | B18: =M11/(M12-M3) -> 2310.1056
A19: PV of terminal value | B19: =B18*L13 -> 1131.1818
A20: Sum of PV of FCFF, years 1-10 | B20: =SUM(C14:L14) -> 619.55353
A21: Operating assets | B21: =B19+B20 -> 1750.7353
A22: Debt | B22: ='Scenario inputs'!D5 -> 86.995
A23: Cash | B23: ='Scenario inputs'!D6 -> 58.13
A24: Minority interests | B24: ='Scenario inputs'!D7 -> 0
A25: Non-operating assets | B25: ='Scenario inputs'!D8 -> 0
A26: Equity value | B26: =B21-B22-B24+B23+B25 -> 1721.8703
A27: Value of employee options | B27: ='Scenario inputs'!D9 -> 0
A28: Common equity | B28: =B26-B27 -> 1721.8703
A29: Shares | B29: ='Scenario inputs'!D10 -> 13.633263
A30: Value per share | B30: =B28/B29 -> 126.29921
A31: PV of terminal value / operating assets | B31: =B19/B21 -> 0.64611811

Sheet DCF Bull
B1: Base year | C1: Year 1 | D1: Year 2 | E1: Year 3 | F1: Year 4 | G1: Year 5 | H1: Year 6 | I1: Year 7 | J1: Year 8 | K1: Year 9 | L1: Year 10 | M1: Terminal year
A2: Year | B2: 0 | C2: 1 | D2: 2 | E2: 3 | F2: 4 | G2: 5 | H2: 6 | I2: 7 | J2: 8 | K2: 9 | L2: 10
A3: Revenue growth | C3: ='Scenario inputs'!E11 -> 0.056477 | D3: ='Scenario inputs'!E12 -> 0.07 | E3: ='Scenario inputs'!E12 -> 0.07 | F3: ='Scenario inputs'!E12 -> 0.07 | G3: ='Scenario inputs'!E12 -> 0.07 | H3: =G3-((G3-M3)/5)*1 -> 0.062 | I3: =G3-((G3-M3)/5)*2 -> 0.054 | J3: =G3-((G3-M3)/5)*3 -> 0.046 | K3: =G3-((G3-M3)/5)*4 -> 0.038 | L3: =G3-((G3-M3)/5)*5 -> 0.03 | M3: ='Scenario inputs'!E13 -> 0.03
A4: Revenue | B4: ='Scenario inputs'!E2 -> 619.985 | C4: =B4*(1+C3) -> 654.99989 | D4: =C4*(1+D3) -> 700.84989 | E4: =D4*(1+E3) -> 749.90938 | F4: =E4*(1+F3) -> 802.40303 | G4: =F4*(1+G3) -> 858.57125 | H4: =G4*(1+H3) -> 911.80266 | I4: =H4*(1+I3) -> 961.04001 | J4: =I4*(1+J3) -> 1005.2478 | ... M4: =L4*(1+M3) -> 1106.9932
A5: Operating margin | B5: =B6/B4 -> 0.17106812 | C5: ='Scenario inputs'!E14 -> 0.174734 | D5: =IF(D2>'Scenario inputs'!E16,'Scenario inputs'!E15,'Scenario inputs'!E15-(('Scenario inputs'!E15-C5)/'Scenario inputs'!E16)*('Scenario inputs'!E16-D2)) -> 0.1848404 | E5: =IF(E2>'Scenario inputs'!E16,'Scenario inputs'!E15,'Scenario inputs'!E15-(('Scenario inputs'!E15-C5)/'Scenario inputs'!E16)*('Scenario inputs'!E16-E2)) -> 0.1898936 | F5: =IF(F2>'Scenario inputs'!E16,'Scenario inputs'!E15,'Scenario inputs'!E15-(('Scenario inputs'!E15-C5)/'Scenario inputs'!E16)*('Scenario inputs'!E16-F2)) -> 0.1949468 | G5: =IF(G2>'Scenario inputs'!E16,'Scenario inputs'!E15,'Scenario inputs'!E15-(('Scenario inputs'!E15-C5)/'Scenario inputs'!E16)*('Scenario inputs'!E16-G2)) -> 0.2 | H5: =IF(H2>'Scenario inputs'!E16,'Scenario inputs'!E15,'Scenario inputs'!E15-(('Scenario inputs'!E15-C5)/'Scenario inputs'!E16)*('Scenario inputs'!E16-H2)) -> 0.2 | I5: =IF(I2>'Scenario inputs'!E16,'Scenario inputs'!E15,'Scenario inputs'!E15-(('Scenario inputs'!E15-C5)/'Scenario inputs'!E16)*('Scenario inputs'!E16-I2)) -> 0.2 | J5: =IF(J2>'Scenario inputs'!E16,'Scenario inputs'!E15,'Scenario inputs'!E15-(('Scenario inputs'!E15-C5)/'Scenario inputs'!E16)*('Scenario inputs'!E16-J2)) -> 0.2 | K5: =IF(K2>'Scenario inputs'!E16,'Scenario inputs'!E15,'Scenario inputs'!E15-(('Scenario inputs'!E15-C5)/'Scenario inputs'!E16)*('Scenario inputs'!E16-K2)) -> 0.2 | L5: =IF(L2>'Scenario inputs'!E16,'Scenario inputs'!E15,'Scenario inputs'!E15-(('Scenario inputs'!E15-C5)/'Scenario inputs'!E16)*('Scenario inputs'!E16-L2)) -> 0.2 | M5: =(L5) -> 0.2
A6: EBIT | B6: ='Scenario inputs'!E3 -> 106.05967 | C6: =C5*C4 -> 114.45075 | D6: =D5*D4 -> 129.54537 | E6: =E5*E4 -> 142.40299 | F6: =F5*F4 -> 156.4259 | G6: =G5*G4 -> 171.71425 | H6: =H5*H4 -> 182.36053 | I6: =I5*I4 -> 192.208 | J6: =J5*J4 -> 201.04957 | ... M6: =M5*M4 -> 221.39864
A7: Tax rate | B7: ='Scenario inputs'!E17 -> 0.225 | C7: =(B7) -> 0.225 | D7: =(C7) -> 0.225 | E7: =(D7) -> 0.225 | F7: =(E7) -> 0.225 | G7: =(F7) -> 0.225 | H7: =G7+(M7-G7)/5 -> 0.23 | I7: =H7+(M7-G7)/5 -> 0.235 | J7: =I7+(M7-G7)/5 -> 0.24 | K7: =J7+(M7-G7)/5 -> 0.245 | L7: =K7+(M7-G7)/5 -> 0.25 | M7: ='Scenario inputs'!E18 -> 0.25
A8: NOPAT | B8: =IF(B6>0,B6*(1-B7),B6) -> 82.196242 | C8: =IF(C6>0,C6*(1-C7),C6) -> 88.699332 | D8: =IF(D6>0,D6*(1-D7),D6) -> 100.39766 | E8: =IF(E6>0,E6*(1-E7),E6) -> 110.36232 | F8: =IF(F6>0,F6*(1-F7),F6) -> 121.23008 | G8: =IF(G6>0,G6*(1-G7),G6) -> 133.07854 | H8: =IF(H6>0,H6*(1-H7),H6) -> 140.41761 | I8: =IF(I6>0,I6*(1-I7),I6) -> 147.03912 | ... L8: =IF(L6>0,L6*(1-L7),L6) -> 161.2126 | M8: =M6*(1-M7) -> 166.04898
A9: Sales to capital | C9: ='Scenario inputs'!E19 -> 2 | D9: ='Scenario inputs'!E19 -> 2 | E9: ='Scenario inputs'!E19 -> 2 | F9: ='Scenario inputs'!E19 -> 2 | G9: ='Scenario inputs'!E19 -> 2 | H9: ='Scenario inputs'!E20 -> 2 | I9: ='Scenario inputs'!E20 -> 2 | J9: ='Scenario inputs'!E20 -> 2 | K9: ='Scenario inputs'!E20 -> 2 | L9: ='Scenario inputs'!E20 -> 2
A10: Reinvestment | C10: =(D4-C4)/C9 -> 22.924996 | D10: =(E4-D4)/D9 -> 24.529746 | E10: =(F4-E4)/E9 -> 26.246828 | F10: =(G4-F4)/F9 -> 28.084106 | G10: =(H4-G4)/G9 -> 26.615709 | H10: =(I4-H4)/H9 -> 24.618672 | I10: =(J4-I4)/I9 -> 22.10392 | J10: =(K4-J4)/J9 -> 19.099709 | ... L10: =(M4-L4)/L9 -> 16.12126 | M10: =IF(M3>0,(M3/B17)*M8,0) -> 24.907347
A11: FCFF | C11: =C8-C10 -> 65.774336 | D11: =D8-D10 -> 75.867918 | E11: =E8-E10 -> 84.11549 | F11: =F8-F10 -> 93.145969 | G11: =G8-G10 -> 106.46283 | H11: =H8-H10 -> 115.79894 | I11: =I8-I10 -> 124.9352 | J11: =J8-J10 -> 133.69796 | ... M11: =M8-M10 -> 141.14163
A12: WACC | C12: ='Scenario inputs'!E21 -> 0.06581 | D12: ='Scenario inputs'!E21 -> 0.06581 | E12: ='Scenario inputs'!E21 -> 0.06581 | F12: ='Scenario inputs'!E21 -> 0.06581 | G12: ='Scenario inputs'!E21 -> 0.06581 | H12: =G12-(G12-M12)/5 -> 0.06581 | I12: =H12-(G12-M12)/5 -> 0.06581 | J12: =I12-(G12-M12)/5 -> 0.06581 | K12: =J12-(G12-M12)/5 -> 0.06581 | L12: =K12-(G12-M12)/5 -> 0.06581 | M12: ='Scenario inputs'!E22 -> 0.06581
A13: Cumulative discount factor | C13: =1/(1+C12) -> 0.93825353 | D13: =C13*(1/(1+D12)) -> 0.8803197 | E13: =D13*(1/(1+E12)) -> 0.82596307 | F13: =E13*(1/(1+F12)) -> 0.77496277 | G13: =F13*(1/(1+G12)) -> 0.72711156 | H13: =G13*(1/(1+H12)) -> 0.68221499 | I13: =H13*(1/(1+I12)) -> 0.64009062 | J13: =I13*(1/(1+J12)) -> 0.60056729 | K13: =J13*(1/(1+K12)) -> 0.56348438 | L13: =K13*(1/(1+L12)) -> 0.52869121
A14: PV of FCFF | C14: =C11*C13 -> 61.713003 | D14: =D11*D13 -> 66.788023 | E14: =E11*E13 -> 69.476288 | F14: =F11*F13 -> 72.184658 | G14: =G11*G13 -> 77.410357 | H14: =H11*H13 -> 78.999771 | I14: =I11*I13 -> 79.969851 | J14: =J11*J13 -> 80.294624 | ... L14: =L11*L13 -> 76.708518
A15: Invested capital | B15: ='Scenario inputs'!E4 -> 313.437 | C15: =B15+C10 -> 336.362 | D15: =C15+D10 -> 360.89174 | E15: =D15+E10 -> 387.13857 | F15: =E15+F10 -> 415.22268 | G15: =F15+G10 -> 441.83839 | H15: =G15+H10 -> 466.45706 | I15: =H15+I10 -> 488.56098 | J15: =I15+J10 -> 507.66069 | ... L15: =K15+L10 -> 539.43366
A16: ROIC | B16: =B8/B15 -> 0.26224167 | C16: =C8/B15 -> 0.28298935 | D16: =D8/C15 -> 0.298481 | E16: =E8/D15 -> 0.3058045 | F16: =F8/E15 -> 0.31314388 | G16: =G8/F15 -> 0.32049922 | H16: =H8/G15 -> 0.3178031 | I16: =I8/H15 -> 0.31522542 | J16: =J8/I15 -> 0.31275046 | ... L16: =L8/K15 -> 0.30806188
A17: Terminal ROIC | B17: =IF('Scenario inputs'!E23=1,'Scenario inputs'!E24,L12) -> 0.2
A18: Terminal value | B18: =M11/(M12-M3) -> 3941.4028
A19: PV of terminal value | B19: =B18*L13 -> 2083.785
A20: Sum of PV of FCFF, years 1-10 | B20: =SUM(C14:L14) -> 743.5085
A21: Operating assets | B21: =B19+B20 -> 2827.2935
A22: Debt | B22: ='Scenario inputs'!E5 -> 86.995
A23: Cash | B23: ='Scenario inputs'!E6 -> 58.13
A24: Minority interests | B24: ='Scenario inputs'!E7 -> 0
A25: Non-operating assets | B25: ='Scenario inputs'!E8 -> 0
A26: Equity value | B26: =B21-B22-B24+B23+B25 -> 2798.4285
A27: Value of employee options | B27: ='Scenario inputs'!E9 -> 0
A28: Common equity | B28: =B26-B27 -> 2798.4285
A29: Shares | B29: ='Scenario inputs'!E10 -> 13.633263
A30: Value per share | B30: =B28/B29 -> 205.26476
A31: PV of terminal value / operating assets | B31: =B19/B21 -> 0.73702465

Sheet EVA Original
B1: Valuation | C1: Year 1 | D1: Year 2 | E1: Year 3 | F1: Year 4 | G1: Year 5 | H1: Year 6 | I1: Year 7 | J1: Year 8 | K1: Year 9 | L1: Year 10
A2: NOPAT | C2: ='DCF Original'!C8 -> 86.640111 | D2: ='DCF Original'!D8 -> 90.972117 | E2: ='DCF Original'!E8 -> 95.520722 | F2: ='DCF Original'!F8 -> 100.29676 | G2: ='DCF Original'!G8 -> 105.3116 | H2: ='DCF Original'!H8 -> 109.25849 | I2: ='DCF Original'!I8 -> 112.80501 | J2: ='DCF Original'!J8 -> 115.90054 | ... L2: ='DCF Original'!L8 -> 120.56162
A3: Opening invested capital | C3: ='DCF Original'!B15 -> 313.437 | D3: ='DCF Original'!C15 -> 329.71161 | E3: ='DCF Original'!D15 -> 346.79994 | F3: ='DCF Original'!E15 -> 364.7427 | G3: ='DCF Original'!F15 -> 383.58259 | H3: ='DCF Original'!G15 -> 401.38628 | I3: ='DCF Original'!H15 -> 417.92394 | J3: ='DCF Original'!I15 -> 432.97321 | ... L3: ='DCF Original'!K15 -> 457.78354
A4: WACC | C4: ='DCF Original'!C12 -> 0.09 | D4: ='DCF Original'!D12 -> 0.09 | E4: ='DCF Original'!E12 -> 0.09 | F4: ='DCF Original'!F12 -> 0.09 | G4: ='DCF Original'!G12 -> 0.09 | H4: ='DCF Original'!H12 -> 0.088 | I4: ='DCF Original'!I12 -> 0.086 | J4: ='DCF Original'!J12 -> 0.084 | ... L4: ='DCF Original'!L12 -> 0.08
A5: Capital charge | C5: =C4*C3 -> 28.20933 | D5: =D4*D3 -> 29.674045 | E5: =E4*E3 -> 31.211995 | F5: =F4*F3 -> 32.826843 | G5: =G4*G3 -> 34.522433 | H5: =H4*H3 -> 35.321993 | I5: =I4*I3 -> 35.941459 | J5: =J4*J3 -> 36.369749 | ... L5: =L4*L3 -> 36.622683
A6: Economic profit | C6: =C2-C5 -> 58.430781 | D6: =D2-D5 -> 61.298072 | E6: =E2-E5 -> 64.308728 | F6: =F2-F5 -> 67.469916 | G6: =G2-G5 -> 70.789164 | H6: =H2-H5 -> 73.936495 | I6: =I2-I5 -> 76.863552 | J6: =J2-J5 -> 79.530788 | ... L6: =L2-L5 -> 83.93894
A7: Cumulative discount factor | C7: ='DCF Original'!C13 -> 0.91743119 | D7: ='DCF Original'!D13 -> 0.84167999 | E7: ='DCF Original'!E13 -> 0.77218348 | F7: ='DCF Original'!F13 -> 0.70842521 | G7: ='DCF Original'!G13 -> 0.64993139 | H7: ='DCF Original'!H13 -> 0.59736341 | I7: ='DCF Original'!I13 -> 0.55005839 | J7: ='DCF Original'!J13 -> 0.50743393 | ... L7: ='DCF Original'!L13 -> 0.43423867
A8: PV of economic profit | C8: =C6*C7 -> 53.606221 | D8: =D6*D7 -> 51.593361 | E8: =E6*E7 -> 49.658137 | F8: =F6*F7 -> 47.797389 | G8: =G6*G7 -> 46.008099 | H8: =H6*H7 -> 44.166956 | I8: =I6*I7 -> 42.279442 | J8: =J6*J7 -> 40.356621 | ... L8: =L6*L7 -> 36.449533
A9: Invested capital, base year | B9: ='DCF Original'!B15 -> 313.437
A10: Sum of PV of economic profit, years 1-10 | B10: =SUM(C8:L8) -> 450.32539
A11: Terminal NOPAT | B11: ='DCF Original'!M8 -> 123.57566
A12: Terminal WACC | B12: ='DCF Original'!M12 -> 0.08
A13: Terminal growth | B13: ='DCF Original'!M3 -> 0.025
A14: Terminal ROIC | B14: ='DCF Original'!B17 -> 0.08
A15: Invested capital, year 10 | B15: ='DCF Original'!L15 -> 469.5295
A16: Economic profit on existing capital, terminal year | B16: =B11-B12*B15 -> 86.013303
A17: Value of economic profit on new capital | B17: =B11*(B13/B14)*(B14-B12)/(B12*(B12-B13)) -> -1.2180091e-13
A18: Continuing value of economic profit | B18: =B16/B12+B17 -> 1075.1663
A19: PV of continuing value | B19: =B18*L7 -> 466.87878
A20: Operating value from economic profit | B20: =B9+B10+B19 -> 1230.6412
A21: Operating value from DCF | B21: ='DCF Original'!B21 -> 1230.6412
A22: Difference (EVA minus DCF) | B22: =B20-B21 -> 0

Sheet EVA Bear
B1: Valuation | C1: Year 1 | D1: Year 2 | E1: Year 3 | F1: Year 4 | G1: Year 5 | H1: Year 6 | I1: Year 7 | J1: Year 8 | K1: Year 9 | L1: Year 10
A2: NOPAT | C2: ='DCF Bear'!C8 -> 78.962236 | D2: ='DCF Bear'!D8 -> 82.120725 | E2: ='DCF Bear'!E8 -> 85.405554 | F2: ='DCF Bear'!F8 -> 88.821776 | G2: ='DCF Bear'!G8 -> 92.374648 | H2: ='DCF Bear'!H8 -> 95.32484 | I2: ='DCF Bear'!I8 -> 97.987931 | J2: ='DCF Bear'!J8 -> 100.33344 | ... L2: ='DCF Bear'!L8 -> 103.96456
A3: Opening invested capital | C3: ='DCF Bear'!B15 -> 313.437 | D3: ='DCF Bear'!C15 -> 326.037 | E3: ='DCF Bear'!D15 -> 339.14101 | F3: ='DCF Bear'!E15 -> 352.76917 | G3: ='DCF Bear'!F15 -> 366.94247 | H3: ='DCF Bear'!G15 -> 380.20867 | I3: ='DCF Bear'!H15 -> 392.42536 | J3: ='DCF Bear'!I15 -> 403.45704 | ... L3: ='DCF Bear'!K15 -> 421.47234
A4: WACC | C4: ='DCF Bear'!C12 -> 0.077021 | D4: ='DCF Bear'!D12 -> 0.077021 | E4: ='DCF Bear'!E12 -> 0.077021 | F4: ='DCF Bear'!F12 -> 0.077021 | G4: ='DCF Bear'!G12 -> 0.077021 | H4: ='DCF Bear'!H12 -> 0.0782594 | I4: ='DCF Bear'!I12 -> 0.0794978 | J4: ='DCF Bear'!J12 -> 0.0807362 | ... L4: ='DCF Bear'!L12 -> 0.083213
A5: Capital charge | C5: =C4*C3 -> 24.141231 | D5: =D4*D3 -> 25.111696 | E5: =E4*E3 -> 26.12098 | F5: =F4*F3 -> 27.170635 | G5: =G4*G3 -> 28.262276 | H5: =H4*H3 -> 29.754902 | I5: =I4*I3 -> 31.196953 | J5: =J4*J3 -> 32.573588 | ... L5: =L4*L3 -> 35.071978
A6: Economic profit | C6: =C2-C5 -> 54.821005 | D6: =D2-D5 -> 57.009029 | E6: =E2-E5 -> 59.284575 | F6: =F2-F5 -> 61.651142 | G6: =G2-G5 -> 64.112372 | H6: =H2-H5 -> 65.569938 | I6: =I2-I5 -> 66.790978 | J6: =J2-J5 -> 67.759856 | ... L6: =L2-L5 -> 68.892582
A7: Cumulative discount factor | C7: ='DCF Bear'!C13 -> 0.928487 | D7: ='DCF Bear'!D13 -> 0.86208811 | E7: ='DCF Bear'!E13 -> 0.80043761 | F7: ='DCF Bear'!F13 -> 0.74319592 | G7: ='DCF Bear'!G13 -> 0.69004775 | H7: ='DCF Bear'!H13 -> 0.63996451 | I7: ='DCF Bear'!I13 -> 0.5928354 | J7: ='DCF Bear'!J13 -> 0.54854774 | ... L7: ='DCF Bear'!L13 -> 0.46804057
A8: PV of economic profit | C8: =C6*C7 -> 50.90059 | D8: =D6*D7 -> 49.146806 | E8: =E6*E7 -> 47.453603 | F8: =F6*F7 -> 45.818877 | G8: =G6*G7 -> 44.240598 | H8: =H6*H7 -> 41.962433 | I8: =I6*I7 -> 39.596056 | J8: =J6*J7 -> 37.169516 | ... L8: =L6*L7 -> 32.244523
A9: Invested capital, base year | B9: ='DCF Bear'!B15 -> 313.437
A10: Sum of PV of economic profit, years 1-10 | B10: =SUM(C8:L8) -> 423.24324
A11: Terminal NOPAT | B11: ='DCF Bear'!M8 -> 106.04385
A12: Terminal WACC | B12: ='DCF Bear'!M12 -> 0.083213
A13: Terminal growth | B13: ='DCF Bear'!M3 -> 0.02
A14: Terminal ROIC | B14: ='DCF Bear'!B17 -> 0.083213
A15: Invested capital, year 10 | B15: ='DCF Bear'!L15 -> 429.93305
A16: Economic profit on existing capital, terminal year | B16: =B11-B12*B15 -> 70.267832
A17: Value of economic profit on new capital | B17: =B11*(B13/B14)*(B14-B12)/(B12*(B12-B13)) -> 6.7242982e-14
A18: Continuing value of economic profit | B18: =B16/B12+B17 -> 844.43335
A19: PV of continuing value | B19: =B18*L7 -> 395.22907
A20: Operating value from economic profit | B20: =B9+B10+B19 -> 1131.9093
A21: Operating value from DCF | B21: ='DCF Bear'!B21 -> 1131.9093
A22: Difference (EVA minus DCF) | B22: =B20-B21 -> 0

Sheet EVA Base
B1: Valuation | C1: Year 1 | D1: Year 2 | E1: Year 3 | F1: Year 4 | G1: Year 5 | H1: Year 6 | I1: Year 7 | J1: Year 8 | K1: Year 9 | L1: Year 10
A2: NOPAT | C2: ='DCF Base'!C8 -> 83.750479 | D2: ='DCF Base'!D8 -> 91.022702 | E2: ='DCF Base'!E8 -> 97.675078 | F2: ='DCF Base'!F8 -> 104.79806 | G2: ='DCF Base'!G8 -> 112.42416 | H2: ='DCF Base'!H8 -> 117.76767 | I2: ='DCF Base'!I8 -> 122.54172 | J2: ='DCF Base'!J8 -> 126.65249 | ... L2: ='DCF Base'!L8 -> 132.55904
A3: Opening invested capital | C3: ='DCF Base'!B15 -> 313.437 | D3: ='DCF Base'!C15 -> 332.71199 | E3: ='DCF Base'!D15 -> 353.14348 | F3: ='DCF Base'!E15 -> 374.80087 | G3: ='DCF Base'!F15 -> 397.75769 | H3: ='DCF Base'!G15 -> 419.25293 | I3: ='DCF Base'!H15 -> 438.89796 | J3: ='DCF Base'!I15 -> 456.31968 | ... L3: ='DCF Base'!K15 -> 483.14654
A4: WACC | C4: ='DCF Base'!C12 -> 0.074014 | D4: ='DCF Base'!D12 -> 0.074014 | E4: ='DCF Base'!E12 -> 0.074014 | F4: ='DCF Base'!F12 -> 0.074014 | G4: ='DCF Base'!G12 -> 0.074014 | H4: ='DCF Base'!H12 -> 0.074014 | I4: ='DCF Base'!I12 -> 0.074014 | J4: ='DCF Base'!J12 -> 0.074014 | ... L4: ='DCF Base'!L12 -> 0.074014
A5: Capital charge | C5: =C4*C3 -> 23.198726 | D5: =D4*D3 -> 24.625345 | E5: =E4*E3 -> 26.137562 | F5: =F4*F3 -> 27.740511 | G5: =G4*G3 -> 29.439638 | H5: =H4*H3 -> 31.030586 | I5: =I4*I3 -> 32.484594 | J5: =J4*J3 -> 33.774045 | ... L5: =L4*L3 -> 35.759608
A6: Economic profit | C6: =C2-C5 -> 60.551753 | D6: =D2-D5 -> 66.397357 | E6: =E2-E5 -> 71.537516 | F6: =F2-F5 -> 77.057545 | G6: =G2-G5 -> 82.984524 | H6: =H2-H5 -> 86.737081 | I6: =I2-I5 -> 90.057123 | J6: =J2-J5 -> 92.878448 | ... L6: =L2-L5 -> 96.799435
A7: Cumulative discount factor | C7: ='DCF Base'!C13 -> 0.93108656 | D7: ='DCF Base'!D13 -> 0.86692218 | E7: ='DCF Base'!E13 -> 0.80717959 | F7: ='DCF Base'!F13 -> 0.75155407 | G7: ='DCF Base'!G13 -> 0.69976189 | H7: ='DCF Base'!H13 -> 0.65153889 | I7: ='DCF Base'!I13 -> 0.60663911 | J7: ='DCF Base'!J13 -> 0.56483352 | ... L7: ='DCF Base'!L13 -> 0.4896667
A8: PV of economic profit | C8: =C6*C7 -> 56.378923 | D8: =D6*D7 -> 57.561342 | E8: =E6*E7 -> 57.743623 | F8: =F6*F7 -> 57.912911 | G8: =G6*G7 -> 58.069407 | H8: =H6*H7 -> 56.512582 | I8: =I6*I7 -> 54.632173 | J8: =J6*J7 -> 52.46086 | ... L8: =L6*L7 -> 47.399461
A9: Invested capital, base year | B9: ='DCF Base'!B15 -> 313.437
A10: Sum of PV of economic profit, years 1-10 | B10: =SUM(C8:L8) -> 548.70747
A11: Terminal NOPAT | B11: ='DCF Base'!M8 -> 135.87302
A12: Terminal WACC | B12: ='DCF Base'!M12 -> 0.074014
A13: Terminal growth | B13: ='DCF Base'!M3 -> 0.025
A14: Terminal ROIC | B14: ='DCF Base'!B17 -> 0.15
A15: Invested capital, year 10 | B15: ='DCF Base'!L15 -> 495.42053
A16: Economic profit on existing capital, terminal year | B16: =B11-B12*B15 -> 99.204965
A17: Value of economic profit on new capital | B17: =B11*(B13/B14)*(B14-B12)/(B12*(B12-B13)) -> 474.33103
A18: Continuing value of economic profit | B18: =B16/B12+B17 -> 1814.6851
A19: PV of continuing value | B19: =B18*L7 -> 888.59086
A20: Operating value from economic profit | B20: =B9+B10+B19 -> 1750.7353
A21: Operating value from DCF | B21: ='DCF Base'!B21 -> 1750.7353
A22: Difference (EVA minus DCF) | B22: =B20-B21 -> 0

Sheet EVA Bull
B1: Valuation | C1: Year 1 | D1: Year 2 | E1: Year 3 | F1: Year 4 | G1: Year 5 | H1: Year 6 | I1: Year 7 | J1: Year 8 | K1: Year 9 | L1: Year 10
A2: NOPAT | C2: ='DCF Bull'!C8 -> 88.699332 | D2: ='DCF Bull'!D8 -> 100.39766 | E2: ='DCF Bull'!E8 -> 110.36232 | F2: ='DCF Bull'!F8 -> 121.23008 | G2: ='DCF Bull'!G8 -> 133.07854 | H2: ='DCF Bull'!H8 -> 140.41761 | I2: ='DCF Bull'!I8 -> 147.03912 | J2: ='DCF Bull'!J8 -> 152.79767 | ... L2: ='DCF Bull'!L8 -> 161.2126
A3: Opening invested capital | C3: ='DCF Bull'!B15 -> 313.437 | D3: ='DCF Bull'!C15 -> 336.362 | E3: ='DCF Bull'!D15 -> 360.89174 | F3: ='DCF Bull'!E15 -> 387.13857 | G3: ='DCF Bull'!F15 -> 415.22268 | H3: ='DCF Bull'!G15 -> 441.83839 | I3: ='DCF Bull'!H15 -> 466.45706 | J3: ='DCF Bull'!I15 -> 488.56098 | ... L3: ='DCF Bull'!K15 -> 523.3124
A4: WACC | C4: ='DCF Bull'!C12 -> 0.06581 | D4: ='DCF Bull'!D12 -> 0.06581 | E4: ='DCF Bull'!E12 -> 0.06581 | F4: ='DCF Bull'!F12 -> 0.06581 | G4: ='DCF Bull'!G12 -> 0.06581 | H4: ='DCF Bull'!H12 -> 0.06581 | I4: ='DCF Bull'!I12 -> 0.06581 | J4: ='DCF Bull'!J12 -> 0.06581 | ... L4: ='DCF Bull'!L12 -> 0.06581
A5: Capital charge | C5: =C4*C3 -> 20.627289 | D5: =D4*D3 -> 22.135983 | E5: =E4*E3 -> 23.750286 | F5: =F4*F3 -> 25.477589 | G5: =G4*G3 -> 27.325804 | H5: =H4*H3 -> 29.077384 | I5: =I4*I3 -> 30.697539 | J5: =J4*J3 -> 32.152198 | ... L5: =L4*L3 -> 34.439189
A6: Economic profit | C6: =C2-C5 -> 68.072043 | D6: =D2-D5 -> 78.261681 | E6: =E2-E5 -> 86.612033 | F6: =F2-F5 -> 95.752486 | G6: =G2-G5 -> 105.75274 | H6: =H2-H5 -> 111.34023 | I6: =I2-I5 -> 116.34158 | J6: =J2-J5 -> 120.64547 | ... L6: =L2-L5 -> 126.77341
A7: Cumulative discount factor | C7: ='DCF Bull'!C13 -> 0.93825353 | D7: ='DCF Bull'!D13 -> 0.8803197 | E7: ='DCF Bull'!E13 -> 0.82596307 | F7: ='DCF Bull'!F13 -> 0.77496277 | G7: ='DCF Bull'!G13 -> 0.72711156 | H7: ='DCF Bull'!H13 -> 0.68221499 | I7: ='DCF Bull'!I13 -> 0.64009062 | J7: ='DCF Bull'!J13 -> 0.60056729 | ... L7: ='DCF Bull'!L13 -> 0.52869121
A8: PV of economic profit | C8: =C6*C7 -> 63.868835 | D8: =D6*D7 -> 68.895299 | E8: =E6*E7 -> 71.53834 | F8: =F6*F7 -> 74.204612 | G8: =G6*G7 -> 76.894038 | H8: =H6*H7 -> 75.957971 | I8: =I6*I7 -> 74.469156 | J8: =J6*J7 -> 72.455726 | ... L8: =L6*L7 -> 67.02399
A9: Invested capital, base year | B9: ='DCF Bull'!B15 -> 313.437
A10: Sum of PV of economic profit, years 1-10 | B10: =SUM(C8:L8) -> 715.26533
A11: Terminal NOPAT | B11: ='DCF Bull'!M8 -> 166.04898
A12: Terminal WACC | B12: ='DCF Bull'!M12 -> 0.06581
A13: Terminal growth | B13: ='DCF Bull'!M3 -> 0.03
A14: Terminal ROIC | B14: ='DCF Bull'!B17 -> 0.2
A15: Invested capital, year 10 | B15: ='DCF Bull'!L15 -> 539.43366
A16: Economic profit on existing capital, terminal year | B16: =B11-B12*B15 -> 130.54885
A17: Value of economic profit on new capital | B17: =B11*(B13/B14)*(B14-B12)/(B12*(B12-B13)) -> 1418.2455
A18: Continuing value of economic profit | B18: =B16/B12+B17 -> 3401.9691
A19: PV of continuing value | B19: =B18*L7 -> 1798.5912
A20: Operating value from economic profit | B20: =B9+B10+B19 -> 2827.2935
A21: Operating value from DCF | B21: ='DCF Bull'!B21 -> 2827.2935
A22: Difference (EVA minus DCF) | B22: =B20-B21 -> 0

Sheet DDM Bear
B1: FY2025 / inputs | C1: Year 1 | D1: Year 2 | E1: Year 3 | F1: Year 4 | G1: Year 5 | H1: Year 6 | I1: Year 7 | J1: Year 8 | K1: Year 9 | L1: Year 10
A2: Year | B2: 0 | C2: 1 | D2: 2 | E2: 3 | F2: 4 | G2: 5 | H2: 6 | I2: 7 | J2: 8 | K2: 9 | L2: 10
A3: EPS | B3: 5.82 | C3: =B3*(1+B9) -> 6.0528 | D3: =C3*(1+B9) -> 6.294912 | E3: =D3*(1+B9) -> 6.5467085 | F3: =E3*(1+B9) -> 6.8085768 | G3: =F3*(1+B9) -> 7.0809199 | H3: =G3*(1+B9) -> 7.3641567 | I3: =H3*(1+B9) -> 7.658723 | J3: =I3*(1+B9) -> 7.9650719 | K3: =J3*(1+B9) -> 8.2836747 | L3: =K3*(1+B9) -> 8.6150217
A4: Payout ratio | B4: =B5/B3 -> 0.64604811 | C4: =(B4) -> 0.64604811 | D4: =(C4) -> 0.64604811 | E4: =(D4) -> 0.64604811 | F4: =(E4) -> 0.64604811 | G4: =(F4) -> 0.64604811 | H4: =(G4) -> 0.64604811 | I4: =(H4) -> 0.64604811 | J4: =(I4) -> 0.64604811 | ... L4: =(K4) -> 0.64604811
A5: Dividend per share | B5: 3.76 | C5: =C3*C4 -> 3.9104 | D5: =D3*D4 -> 4.066816 | E5: =E3*E4 -> 4.2294886 | F5: =F3*F4 -> 4.3986682 | G5: =G3*G4 -> 4.5746149 | H5: =H3*H4 -> 4.7575995 | I5: =I3*I4 -> 4.9479035 | J5: =J3*J4 -> 5.1458196 | ... L5: =L3*L4 -> 5.5657185
A6: Discount factor | C6: =1/(1+B8)^C2 -> 0.92762389 | D6: =1/(1+B8)^D2 -> 0.86048608 | E6: =1/(1+B8)^E2 -> 0.79820745 | F6: =1/(1+B8)^F2 -> 0.7404363 | G6: =1/(1+B8)^G2 -> 0.6868464 | H6: =1/(1+B8)^H2 -> 0.63713513 | I6: =1/(1+B8)^I2 -> 0.59102177 | J6: =1/(1+B8)^J2 -> 0.54824592 | K6: =1/(1+B8)^K2 -> 0.50856601 | L6: =1/(1+B8)^L2 -> 0.47175798
A7: PV of dividend | C7: =C5*C6 -> 3.6273805 | D7: =D5*D6 -> 3.4994386 | E7: =E5*E6 -> 3.3760093 | F7: =F5*F6 -> 3.2569336 | G7: =G5*G6 -> 3.1420578 | H7: =H5*H6 -> 3.0312338 | I7: =I5*I6 -> 2.9243187 | J7: =J5*J6 -> 2.8211746 | ... L7: =L5*L6 -> 2.6256721
A8: Cost of equity | B8: 0.078023118
A9: EPS growth, years 1-10 | B9: 0.04
A10: Terminal growth | B10: 0.02
A11: Terminal return on equity | B11: 0.078023118
A12: Terminal payout ratio | B12: =1-B10/B11 -> 0.74366572
A13: Dividend, year 11 | B13: =L3*(1+B10)*B12 -> 6.5348302
A14: Terminal value, end of year 10 | B14: =B13/(B8-B10) -> 112.6246
A15: PV of terminal value | B15: =B14*L6 -> 53.131552
A16: Sum of PV of dividends, years 1-10 | B16: =SUM(C7:L7) -> 31.025888
A17: Value per share | B17: =B16+B15 -> 84.15744

Sheet DDM Base
B1: FY2025 / inputs | C1: Year 1 | D1: Year 2 | E1: Year 3 | F1: Year 4 | G1: Year 5 | H1: Year 6 | I1: Year 7 | J1: Year 8 | K1: Year 9 | L1: Year 10
A2: Year | B2: 0 | C2: 1 | D2: 2 | E2: 3 | F2: 4 | G2: 5 | H2: 6 | I2: 7 | J2: 8 | K2: 9 | L2: 10
A3: EPS | B3: 5.82 | C3: =B3*(1+B9) -> 6.1692 | D3: =C3*(1+B9) -> 6.539352 | E3: =D3*(1+B9) -> 6.9317131 | F3: =E3*(1+B9) -> 7.3476159 | G3: =F3*(1+B9) -> 7.7884729 | H3: =G3*(1+B9) -> 8.2557812 | I3: =H3*(1+B9) -> 8.7511281 | J3: =I3*(1+B9) -> 9.2761958 | K3: =J3*(1+B9) -> 9.8327675 | L3: =K3*(1+B9) -> 10.422734
A4: Payout ratio | B4: =B5/B3 -> 0.64604811 | C4: =(B4) -> 0.64604811 | D4: =(C4) -> 0.64604811 | E4: =(D4) -> 0.64604811 | F4: =(E4) -> 0.64604811 | G4: =(F4) -> 0.64604811 | H4: =(G4) -> 0.64604811 | I4: =(H4) -> 0.64604811 | J4: =(I4) -> 0.64604811 | ... L4: =(K4) -> 0.64604811
A5: Dividend per share | B5: 3.76 | C5: =C3*C4 -> 3.9856 | D5: =D3*D4 -> 4.224736 | E5: =E3*E4 -> 4.4782202 | F5: =F3*F4 -> 4.7469134 | G5: =G3*G4 -> 5.0317282 | H5: =H3*H4 -> 5.3336319 | I5: =I3*I4 -> 5.6536498 | J5: =J3*J4 -> 5.9928688 | ... L5: =L3*L4 -> 6.7335873
A6: Discount factor | C6: =1/(1+B8)^C2 -> 0.93029617 | D6: =1/(1+B8)^D2 -> 0.86545096 | E6: =1/(1+B8)^E2 -> 0.80512572 | F6: =1/(1+B8)^F2 -> 0.74900537 | G6: =1/(1+B8)^G2 -> 0.69679683 | H6: =1/(1+B8)^H2 -> 0.64822742 | I6: =1/(1+B8)^I2 -> 0.60304348 | J6: =1/(1+B8)^J2 -> 0.56100904 | K6: =1/(1+B8)^K2 -> 0.52190456 | L6: =1/(1+B8)^L2 -> 0.48552582
A7: PV of dividend | C7: =C5*C6 -> 3.7077884 | D7: =D5*D6 -> 3.6563018 | E7: =E5*E6 -> 3.6055302 | F7: =F5*F6 -> 3.5554636 | G7: =G5*G6 -> 3.5060922 | H7: =H5*H6 -> 3.4574064 | I7: =I5*I6 -> 3.4093967 | J7: =J5*J6 -> 3.3620536 | ... L7: =L5*L6 -> 3.2693305
A8: Cost of equity | B8: 0.074926494
A9: EPS growth, years 1-10 | B9: 0.06
A10: Terminal growth | B10: 0.025
A11: Terminal return on equity | B11: 0.15
A12: Terminal payout ratio | B12: =1-B10/B11 -> 0.83333333
A13: Dividend, year 11 | B13: =L3*(1+B10)*B12 -> 8.9027516
A14: Terminal value, end of year 10 | B14: =B13/(B8-B10) -> 178.31718
A15: PV of terminal value | B15: =B14*L6 -> 86.577594
A16: Sum of PV of dividends, years 1-10 | B16: =SUM(C7:L7) -> 34.844731
A17: Value per share | B17: =B16+B15 -> 121.42232

Sheet DDM Bull
B1: FY2025 / inputs | C1: Year 1 | D1: Year 2 | E1: Year 3 | F1: Year 4 | G1: Year 5 | H1: Year 6 | I1: Year 7 | J1: Year 8 | K1: Year 9 | L1: Year 10
A2: Year | B2: 0 | C2: 1 | D2: 2 | E2: 3 | F2: 4 | G2: 5 | H2: 6 | I2: 7 | J2: 8 | K2: 9 | L2: 10
A3: EPS | B3: 5.82 | C3: =B3*(1+B9) -> 6.2856 | D3: =C3*(1+B9) -> 6.788448 | E3: =D3*(1+B9) -> 7.3315238 | F3: =E3*(1+B9) -> 7.9180457 | G3: =F3*(1+B9) -> 8.5514894 | H3: =G3*(1+B9) -> 9.2356086 | I3: =H3*(1+B9) -> 9.9744572 | J3: =I3*(1+B9) -> 10.772414 | K3: =J3*(1+B9) -> 11.634207 | L3: =K3*(1+B9) -> 12.564943
A4: Payout ratio | B4: =B5/B3 -> 0.64604811 | C4: =(B4) -> 0.64604811 | D4: =(C4) -> 0.64604811 | E4: =(D4) -> 0.64604811 | F4: =(E4) -> 0.64604811 | G4: =(F4) -> 0.64604811 | H4: =(G4) -> 0.64604811 | I4: =(H4) -> 0.64604811 | J4: =(I4) -> 0.64604811 | ... L4: =(K4) -> 0.64604811
A5: Dividend per share | B5: 3.76 | C5: =C3*C4 -> 4.0608 | D5: =D3*D4 -> 4.385664 | E5: =E3*E4 -> 4.7365171 | F5: =F3*F4 -> 5.1154385 | G5: =G3*G4 -> 5.5246736 | H5: =H3*H4 -> 5.9666475 | I5: =I3*I4 -> 6.4439793 | J5: =J3*J4 -> 6.9594976 | ... L5: =L3*L4 -> 8.117558
A6: Discount factor | C6: =1/(1+B8)^C2 -> 0.93766522 | D6: =1/(1+B8)^D2 -> 0.87921606 | E6: =1/(1+B8)^E2 -> 0.82441032 | F6: =1/(1+B8)^F2 -> 0.77302088 | G6: =1/(1+B8)^G2 -> 0.7248348 | H6: =1/(1+B8)^H2 -> 0.67965238 | I6: =1/(1+B8)^I2 -> 0.63728639 | J6: =1/(1+B8)^J2 -> 0.59756129 | K6: =1/(1+B8)^K2 -> 0.56031243 | L6: =1/(1+B8)^L2 -> 0.52538548
A7: PV of dividend | C7: =C5*C6 -> 3.8076709 | D7: =D5*D6 -> 3.8559462 | E7: =E5*E6 -> 3.9048336 | F7: =F5*F6 -> 3.9543408 | G7: =G5*G6 -> 4.0044756 | H7: =H5*H6 -> 4.0552461 | I7: =I5*I6 -> 4.1066603 | J7: =J5*J6 -> 4.1587263 | ... L7: =L5*L6 -> 4.2648471
A8: Cost of equity | B8: 0.066478718
A9: EPS growth, years 1-10 | B9: 0.08
A10: Terminal growth | B10: 0.03
A11: Terminal return on equity | B11: 0.2
A12: Terminal payout ratio | B12: =1-B10/B11 -> 0.85
A13: Dividend, year 11 | B13: =L3*(1+B10)*B12 -> 11.000608
A14: Terminal value, end of year 10 | B14: =B13/(B8-B10) -> 301.56235
A15: PV of terminal value | B15: =B14*L6 -> 158.43648
A16: Sum of PV of dividends, years 1-10 | B16: =SUM(C7:L7) -> 40.3242
A17: Value per share | B17: =B16+B15 -> 198.76068

Sheet LBO Bear
B1: Entry / FY2025 | C1: Year 1 | D1: Year 2 | E1: Year 3 | F1: Year 4 | G1: Year 5
A2: Entry price per share | B2: 66.132812
A3: Diluted shares (m) | B3: 13.633263
A4: Equity purchase price | B4: =B2*B3 -> 901.60603
A5: Existing debt refinanced | B5: 86.995
A6: Cash at entry | B6: 58.13
A7: Minimum cash | B7: 30
A8: Entry enterprise value | B8: =B4+B5-B6 -> 930.47103
A9: EBITDA FY2025 | B9: 111.984
A10: Entry EV / EBITDA | B10: =B8/B9 -> 8.308964
A11: Leverage (x FY2025 EBITDA) | B11: 4.5
A12: New debt | B12: =B11*B9 -> 503.928
A13: SOFR, 29 Aug 2025 | B13: 0.0434
A14: Credit spread | B14: 0.035
A15: Interest rate | B15: =B13+B14 -> 0.0784
A16: Transaction fees (% of entry EV) | B16: 0.02
A17: Financing fees (% of new debt) | B17: 0.025
A18: Total uses | B18: =B4+B5+B8*B16+B12*B17 -> 1019.8086
A19: Excess cash used | B19: =B6-B7 -> 28.13
A20: Sponsor equity | B20: =B18-B12-B19 -> 487.75065
A21: Revenue | C21: ='DCF Base'!C4 -> 642.49976 | D21: ='DCF Base'!D4 -> 681.04974 | E21: ='DCF Base'!E4 -> 721.91273 | F21: ='DCF Base'!F4 -> 765.22749 | G21: ='DCF Base'!G4 -> 811.14114
A22: EBITDA (reported basis) | C22: ='DCF Base'!C6+C21*(B39-B38) -> 114.90633 | D22: ='DCF Base'!D6+D21*(B39-B38) -> 124.71915 | E22: ='DCF Base'!E6+E21*(B39-B38) -> 133.74906 | F22: ='DCF Base'!F6+F21*(B39-B38) -> 143.41359 | G22: ='DCF Base'!G6+G21*(B39-B38) -> 153.75635
A23: FCFF before financing (DCF Base) | C23: ='DCF Base'!C11 -> 64.475487 | D23: ='DCF Base'!D11 -> 70.59121 | E23: ='DCF Base'!E11 -> 76.017696 | F23: ='DCF Base'!F11 -> 81.841231 | G23: ='DCF Base'!G11 -> 90.928922
A24: Interest | C24: =B15*B12 -> 39.507955 | D24: =B15*C29 -> 36.838093 | E24: =B15*D29 -> 33.527584 | F24: =B15*E29 -> 29.59179 | G24: =B15*F29 -> 24.961835
A25: Tax rate | C25: ='DCF Base'!C7 -> 0.23 | D25: ='DCF Base'!D7 -> 0.23 | E25: ='DCF Base'!E7 -> 0.23 | F25: ='DCF Base'!F7 -> 0.23 | G25: ='DCF Base'!G7 -> 0.23
A26: After-tax interest | C26: =C24*(1-C25) -> 30.421126 | D26: =D24*(1-D25) -> 28.365332 | E26: =E24*(1-E25) -> 25.81624 | F26: =F24*(1-F25) -> 22.785679 | G26: =G24*(1-G25) -> 19.220613
A27: Cash flow after interest | C27: =C23-C26 -> 34.054361 | D27: =D23-D26 -> 42.225878 | E27: =E23-E26 -> 50.201456 | F27: =F23-F26 -> 59.055553 | G27: =G23-G26 -> 71.708309
A28: Debt repaid | C28: =IF(C27>B12,B12,C27) -> 34.054361 | D28: =IF(D27>C29,C29,D27) -> 42.225878 | E28: =IF(E27>D29,D29,E27) -> 50.201456 | F28: =IF(F27>E29,E29,F27) -> 59.055553 | G28: =IF(G27>F29,F29,G27) -> 71.708309
A29: Debt, end of year | B29: =B12 -> 503.928 | C29: =B12-C28 -> 469.87364 | D29: =C29-D28 -> 427.64776 | E29: =D29-E28 -> 377.4463 | F29: =E29-F28 -> 318.39075 | G29: =F29-G28 -> 246.68244
A30: Cash, end of year | B30: =B7 -> 30 | C30: =B7+C27-C28 -> 30 | D30: =C30+D27-D28 -> 30 | E30: =D30+E27-E28 -> 30 | F30: =E30+F27-F28 -> 30 | G30: =F30+G27-G28 -> 30
A31: Exit EV / EBITDA | B31: 11.090646
A32: Exit enterprise value | B32: =B31*G22 -> 1705.2573
A33: Exit equity value | B33: =B32-G29+G30 -> 1488.5749
A34: MOIC | B34: =B33/B20 -> 3.0519178
A35: IRR | B35: =B34^(1/5)-1 -> 0.25001311
A36: Hurdle IRR | B36: 0.25
A37: Meets hurdle (1 = yes) | B37: =IF(B35>=B36,1,0) -> 1
A38: R&D capitalization adjustment (% of revenue) | B38: 0.0036560024
A39: D&A (% of revenue) | B39: 0.01321161

Sheet LBO Base
B1: Entry / FY2025 | C1: Year 1 | D1: Year 2 | E1: Year 3 | F1: Year 4 | G1: Year 5
A2: Entry price per share | B2: 76.152344
A3: Diluted shares (m) | B3: 13.633263
A4: Equity purchase price | B4: =B2*B3 -> 1038.2049
A5: Existing debt refinanced | B5: 86.995
A6: Cash at entry | B6: 58.13
A7: Minimum cash | B7: 30
A8: Entry enterprise value | B8: =B4+B5-B6 -> 1067.0699
A9: EBITDA FY2025 | B9: 111.984
A10: Entry EV / EBITDA | B10: =B8/B9 -> 9.5287713
A11: Leverage (x FY2025 EBITDA) | B11: 5
A12: New debt | B12: =B11*B9 -> 559.92
A13: SOFR, 29 Aug 2025 | B13: 0.0434
A14: Credit spread | B14: 0.035
A15: Interest rate | B15: =B13+B14 -> 0.0784
A16: Transaction fees (% of entry EV) | B16: 0.02
A17: Financing fees (% of new debt) | B17: 0.025
A18: Total uses | B18: =B4+B5+B8*B16+B12*B17 -> 1160.5393
A19: Excess cash used | B19: =B6-B7 -> 28.13
A20: Sponsor equity | B20: =B18-B12-B19 -> 572.48933
A21: Revenue | C21: ='DCF Base'!C4 -> 642.49976 | D21: ='DCF Base'!D4 -> 681.04974 | E21: ='DCF Base'!E4 -> 721.91273 | F21: ='DCF Base'!F4 -> 765.22749 | G21: ='DCF Base'!G4 -> 811.14114
A22: EBITDA (reported basis) | C22: ='DCF Base'!C6+C21*(B39-B38) -> 114.90633 | D22: ='DCF Base'!D6+D21*(B39-B38) -> 124.71915 | E22: ='DCF Base'!E6+E21*(B39-B38) -> 133.74906 | F22: ='DCF Base'!F6+F21*(B39-B38) -> 143.41359 | G22: ='DCF Base'!G6+G21*(B39-B38) -> 153.75635
A23: FCFF before financing (DCF Base) | C23: ='DCF Base'!C11 -> 64.475487 | D23: ='DCF Base'!D11 -> 70.59121 | E23: ='DCF Base'!E11 -> 76.017696 | F23: ='DCF Base'!F11 -> 81.841231 | G23: ='DCF Base'!G11 -> 90.928922
A24: Interest | C24: =B15*B12 -> 43.897728 | D24: =B15*C29 -> 41.492868 | E24: =B15*D29 -> 38.463358 | F24: =B15*E29 -> 34.825527 | G24: =B15*F29 -> 30.511522
A25: Tax rate | C25: ='DCF Base'!C7 -> 0.23 | D25: ='DCF Base'!D7 -> 0.23 | E25: ='DCF Base'!E7 -> 0.23 | F25: ='DCF Base'!F7 -> 0.23 | G25: ='DCF Base'!G7 -> 0.23
A26: After-tax interest | C26: =C24*(1-C25) -> 33.801251 | D26: =D24*(1-D25) -> 31.949508 | E26: =E24*(1-E25) -> 29.616786 | F26: =F24*(1-F25) -> 26.815656 | G26: =G24*(1-G25) -> 23.493872
A27: Cash flow after interest | C27: =C23-C26 -> 30.674236 | D27: =D23-D26 -> 38.641702 | E27: =E23-E26 -> 46.40091 | F27: =F23-F26 -> 55.025576 | G27: =G23-G26 -> 67.43505
A28: Debt repaid | C28: =IF(C27>B12,B12,C27) -> 30.674236 | D28: =IF(D27>C29,C29,D27) -> 38.641702 | E28: =IF(E27>D29,D29,E27) -> 46.40091 | F28: =IF(F27>E29,E29,F27) -> 55.025576 | G28: =IF(G27>F29,F29,G27) -> 67.43505
A29: Debt, end of year | B29: =B12 -> 559.92 | C29: =B12-C28 -> 529.24576 | D29: =C29-D28 -> 490.60406 | E29: =D29-E28 -> 444.20315 | F29: =E29-F28 -> 389.17758 | G29: =F29-G28 -> 321.74253
A30: Cash, end of year | B30: =B7 -> 30 | C30: =B7+C27-C28 -> 30 | D30: =C30+D27-D28 -> 30 | E30: =D30+E27-E28 -> 30 | F30: =E30+F27-F28 -> 30 | G30: =F30+G27-G28 -> 30
A31: Exit EV / EBITDA | B31: 11.162989
A32: Exit enterprise value | B32: =B31*G22 -> 1716.3804
A33: Exit equity value | B33: =B32-G29+G30 -> 1424.6379
A34: MOIC | B34: =B33/B20 -> 2.4884969
A35: IRR | B35: =B34^(1/5)-1 -> 0.20001706
A36: Hurdle IRR | B36: 0.2
A37: Meets hurdle (1 = yes) | B37: =IF(B35>=B36,1,0) -> 1
A38: R&D capitalization adjustment (% of revenue) | B38: 0.0036560024
A39: D&A (% of revenue) | B39: 0.01321161

Sheet LBO Bull
B1: Entry / FY2025 | C1: Year 1 | D1: Year 2 | E1: Year 3 | F1: Year 4 | G1: Year 5
A2: Entry price per share | B2: 108.4082
A3: Diluted shares (m) | B3: 13.633263
A4: Equity purchase price | B4: =B2*B3 -> 1477.9575
A5: Existing debt refinanced | B5: 86.995
A6: Cash at entry | B6: 58.13
A7: Minimum cash | B7: 30
A8: Entry enterprise value | B8: =B4+B5-B6 -> 1506.8225
A9: EBITDA FY2025 | B9: 111.984
A10: Entry EV / EBITDA | B10: =B8/B9 -> 13.455695
A11: Leverage (x FY2025 EBITDA) | B11: 5.5
A12: New debt | B12: =B11*B9 -> 615.912
A13: SOFR, 29 Aug 2025 | B13: 0.0434
A14: Credit spread | B14: 0.035
A15: Interest rate | B15: =B13+B14 -> 0.0784
A16: Transaction fees (% of entry EV) | B16: 0.02
A17: Financing fees (% of new debt) | B17: 0.025
A18: Total uses | B18: =B4+B5+B8*B16+B12*B17 -> 1610.4868
A19: Excess cash used | B19: =B6-B7 -> 28.13
A20: Sponsor equity | B20: =B18-B12-B19 -> 966.4448
A21: Revenue | C21: ='DCF Base'!C4 -> 642.49976 | D21: ='DCF Base'!D4 -> 681.04974 | E21: ='DCF Base'!E4 -> 721.91273 | F21: ='DCF Base'!F4 -> 765.22749 | G21: ='DCF Base'!G4 -> 811.14114
A22: EBITDA (reported basis) | C22: ='DCF Base'!C6+C21*(B39-B38) -> 114.90633 | D22: ='DCF Base'!D6+D21*(B39-B38) -> 124.71915 | E22: ='DCF Base'!E6+E21*(B39-B38) -> 133.74906 | F22: ='DCF Base'!F6+F21*(B39-B38) -> 143.41359 | G22: ='DCF Base'!G6+G21*(B39-B38) -> 153.75635
A23: FCFF before financing (DCF Base) | C23: ='DCF Base'!C11 -> 64.475487 | D23: ='DCF Base'!D11 -> 70.59121 | E23: ='DCF Base'!E11 -> 76.017696 | F23: ='DCF Base'!F11 -> 81.841231 | G23: ='DCF Base'!G11 -> 90.928922
A24: Interest | C24: =B15*B12 -> 48.287501 | D24: =B15*C29 -> 46.147643 | E24: =B15*D29 -> 43.399133 | F24: =B15*E29 -> 40.059264 | G24: =B15*F29 -> 36.061209
A25: Tax rate | C25: ='DCF Base'!C7 -> 0.23 | D25: ='DCF Base'!D7 -> 0.23 | E25: ='DCF Base'!E7 -> 0.23 | F25: ='DCF Base'!F7 -> 0.23 | G25: ='DCF Base'!G7 -> 0.23
A26: After-tax interest | C26: =C24*(1-C25) -> 37.181376 | D26: =D24*(1-D25) -> 35.533685 | E26: =E24*(1-E25) -> 33.417332 | F26: =F24*(1-F25) -> 30.845633 | G26: =G24*(1-G25) -> 27.767131
A27: Cash flow after interest | C27: =C23-C26 -> 27.294111 | D27: =D23-D26 -> 35.057525 | E27: =E23-E26 -> 42.600364 | F27: =F23-F26 -> 50.995598 | G27: =G23-G26 -> 63.161791
A28: Debt repaid | C28: =IF(C27>B12,B12,C27) -> 27.294111 | D28: =IF(D27>C29,C29,D27) -> 35.057525 | E28: =IF(E27>D29,D29,E27) -> 42.600364 | F28: =IF(F27>E29,E29,F27) -> 50.995598 | G28: =IF(G27>F29,F29,G27) -> 63.161791
A29: Debt, end of year | B29: =B12 -> 615.912 | C29: =B12-C28 -> 588.61789 | D29: =C29-D28 -> 553.56036 | E29: =D29-E28 -> 510.96 | F29: =E29-F28 -> 459.9644 | G29: =F29-G28 -> 396.80261
A30: Cash, end of year | B30: =B7 -> 30 | C30: =B7+C27-C28 -> 30 | D30: =C30+D27-D28 -> 30 | E30: =D30+E27-E28 -> 30 | F30: =E30+F27-F28 -> 30 | G30: =F30+G27-G28 -> 30
A31: Exit EV / EBITDA | B31: 16.464255
A32: Exit enterprise value | B32: =B31*G22 -> 2531.4838
A33: Exit equity value | B33: =B32-G29+G30 -> 2164.6812
A34: MOIC | B34: =B33/B20 -> 2.2398394
A35: IRR | B35: =B34^(1/5)-1 -> 0.17501491
A36: Hurdle IRR | B36: 0.175
A37: Meets hurdle (1 = yes) | B37: =IF(B35>=B36,1,0) -> 1
